[INFO][2024-10-27 16:49:44][config.py:302] - [INIT] load config: {'channel_type': 'wx', 'model': 'coze', 'coze_api_base': 'https://api.coze.cn/open_api/v2', 'coze_api_key': 'pat*****hv8', 'coze_bot_id': '7430312631141318675', 'text_to_image': 'dall-e-2', 'voice_to_text': 'openai', 'text_to_voice': 'openai', 'proxy': '', 'hot_reload': False, 'single_chat_prefix': ['bot', '@bot'], 'single_chat_reply_prefix': '[bot] ', 'group_chat_prefix': ['@bot'], 'group_name_white_list': ['ChatGPT测试群', '自己人测试群'], 'image_create_prefix': ['画'], 'speech_recognition': True, 'group_speech_recognition': False, 'voice_reply_voice': False, 'conversation_max_tokens': 2500, 'expires_in_seconds': 3600, 'character_desc': '你是基于大语言模型的AI智能助手，旨在回答并解决人们的任何问题，并且可以使用多种语言与人交流。', 'temperature': 0.7, 'subscribe_msg': '感谢您的关注！\n这里是AI智能助手，可以自由对话。\n支持语音对话。\n支持图片输入。\n支持图片输出，画字开头的消息将按要求创作图片。\n支持tool、角色扮演和文字冒险等丰富的插件。\n输入{trigger_prefix}#help 查看详细指令。', 'use_linkai': False, 'linkai_api_key': '*****', 'linkai_app_code': ''}
[INFO][2024-10-27 16:49:44][config.py:226] - [Config] User datas loaded.
[INFO][2024-10-27 16:49:45][plugin_manager.py:50] - Loading plugins config...
[INFO][2024-10-27 16:49:45][plugin_manager.py:88] - Scaning plugins ...
[INFO][2024-10-27 16:49:45][plugin_manager.py:41] - Plugin Banwords_v1.0 registered, path=./plugins\banwords
[INFO][2024-10-27 16:49:45][plugin_manager.py:41] - Plugin BDunit_v0.1 registered, path=./plugins\bdunit
[INFO][2024-10-27 16:49:45][plugin_manager.py:41] - Plugin Dungeon_v1.0 registered, path=./plugins\dungeon
[INFO][2024-10-27 16:49:45][plugin_manager.py:41] - Plugin Finish_v1.0 registered, path=./plugins\finish
[INFO][2024-10-27 16:49:45][plugin_manager.py:41] - Plugin Godcmd_v1.0 registered, path=./plugins\godcmd
[INFO][2024-10-27 16:49:45][plugin_manager.py:41] - Plugin Hello_v0.1 registered, path=./plugins\hello
[INFO][2024-10-27 16:49:45][plugin_manager.py:41] - Plugin Keyword_v0.1 registered, path=./plugins\keyword
[INFO][2024-10-27 16:49:45][plugin_manager.py:41] - Plugin linkai_v0.1.0 registered, path=./plugins\linkai
[INFO][2024-10-27 16:49:45][plugin_manager.py:41] - Plugin Role_v1.0 registered, path=./plugins\role
[WARNING][2024-10-27 16:49:45][plugin_manager.py:113] - Failed to import plugin tool: No module named 'chatgpt_tool_hub'
[INFO][2024-10-27 16:49:45][godcmd.py:194] - [Godcmd] 因未设置口令，本次的临时口令为7902。
[INFO][2024-10-27 16:49:45][godcmd.py:210] - [Godcmd] inited
[INFO][2024-10-27 16:49:45][keyword.py:40] - [keyword] {}
[INFO][2024-10-27 16:49:45][keyword.py:42] - [keyword] inited.
[INFO][2024-10-27 16:49:45][linkai.py:35] - [LinkAI] inited, config={'group_app_map': {'测试群名1': 'default', '测试群名2': 'Kv2fXJcH'}, 'midjourney': {'enabled': False, 'auto_translate': True, 'img_proxy': True, 'max_tasks': 3, 'max_tasks_per_user': 1, 'use_image_create_prefix': True}, 'summary': {'enabled': False, 'group_enabled': True, 'max_file_size': 5000, 'type': ['FILE', 'SHARING']}}
[INFO][2024-10-27 16:49:45][role.py:69] - [Role] inited
[INFO][2024-10-27 16:49:45][dungeon.py:56] - [Dungeon] inited
[INFO][2024-10-27 16:49:45][hello.py:38] - [Hello] inited
[INFO][2024-10-27 16:49:45][finish.py:23] - [Finish] inited
[ERROR][2024-10-27 16:49:46][wechat_channel.py:135] - No module named 'png'
Traceback (most recent call last):
  File "E:\code\cozewechat\chatgpt-on-wechat\channel\wechat\wechat_channel.py", line 121, in startup
    itchat.auto_login(
  File "E:\code\cozewechat\chatgpt-on-wechat\lib\itchat\components\register.py", line 38, in auto_login
    self.login(enableCmdQR=enableCmdQR, picDir=picDir, qrCallback=qrCallback,
  File "E:\code\cozewechat\chatgpt-on-wechat\lib\itchat\components\login.py", line 56, in login
    qrStorage = self.get_QR(enableCmdQR=enableCmdQR,
                ^^^^^^^^^^^^^^^^^^^^^^^^^^^^^^^^^^^^
  File "E:\code\cozewechat\chatgpt-on-wechat\lib\itchat\components\login.py", line 130, in get_QR
    qrCode.png(qrStorage, scale=10)
  File "C:\Users\Administrator\AppData\Local\Programs\Python\Python311\Lib\site-packages\pyqrcode\__init__.py", line 462, in png
    builder._png(self.code, self.version, file, scale,
  File "C:\Users\Administrator\AppData\Local\Programs\Python\Python311\Lib\site-packages\pyqrcode\builder.py", line 1266, in _png
    import png
ModuleNotFoundError: No module named 'png'
[INFO][2024-10-27 16:51:15][config.py:302] - [INIT] load config: {'channel_type': 'wx', 'model': 'coze', 'coze_api_base': 'https://api.coze.cn/open_api/v2', 'coze_api_key': 'pat*****hv8', 'coze_bot_id': '7430312631141318675', 'text_to_image': 'dall-e-2', 'voice_to_text': 'openai', 'text_to_voice': 'openai', 'proxy': '', 'hot_reload': False, 'single_chat_prefix': ['bot', '@bot'], 'single_chat_reply_prefix': '[bot] ', 'group_chat_prefix': ['@bot'], 'group_name_white_list': ['ChatGPT测试群', '自己人测试群'], 'image_create_prefix': ['画'], 'speech_recognition': True, 'group_speech_recognition': False, 'voice_reply_voice': False, 'conversation_max_tokens': 2500, 'expires_in_seconds': 3600, 'character_desc': '你是基于大语言模型的AI智能助手，旨在回答并解决人们的任何问题，并且可以使用多种语言与人交流。', 'temperature': 0.7, 'subscribe_msg': '感谢您的关注！\n这里是AI智能助手，可以自由对话。\n支持语音对话。\n支持图片输入。\n支持图片输出，画字开头的消息将按要求创作图片。\n支持tool、角色扮演和文字冒险等丰富的插件。\n输入{trigger_prefix}#help 查看详细指令。', 'use_linkai': False, 'linkai_api_key': '*****', 'linkai_app_code': ''}
[INFO][2024-10-27 16:51:15][config.py:226] - [Config] User datas loaded.
[INFO][2024-10-27 16:51:15][plugin_manager.py:50] - Loading plugins config...
[INFO][2024-10-27 16:51:15][plugin_manager.py:88] - Scaning plugins ...
[INFO][2024-10-27 16:51:15][plugin_manager.py:41] - Plugin Banwords_v1.0 registered, path=./plugins\banwords
[INFO][2024-10-27 16:51:15][plugin_manager.py:41] - Plugin BDunit_v0.1 registered, path=./plugins\bdunit
[INFO][2024-10-27 16:51:15][plugin_manager.py:41] - Plugin Dungeon_v1.0 registered, path=./plugins\dungeon
[INFO][2024-10-27 16:51:15][plugin_manager.py:41] - Plugin Finish_v1.0 registered, path=./plugins\finish
[INFO][2024-10-27 16:51:15][plugin_manager.py:41] - Plugin Godcmd_v1.0 registered, path=./plugins\godcmd
[INFO][2024-10-27 16:51:15][plugin_manager.py:41] - Plugin Hello_v0.1 registered, path=./plugins\hello
[INFO][2024-10-27 16:51:15][plugin_manager.py:41] - Plugin Keyword_v0.1 registered, path=./plugins\keyword
[INFO][2024-10-27 16:51:15][plugin_manager.py:41] - Plugin linkai_v0.1.0 registered, path=./plugins\linkai
[INFO][2024-10-27 16:51:15][plugin_manager.py:41] - Plugin Role_v1.0 registered, path=./plugins\role
[WARNING][2024-10-27 16:51:15][plugin_manager.py:113] - Failed to import plugin tool: No module named 'chatgpt_tool_hub'
[INFO][2024-10-27 16:51:15][godcmd.py:194] - [Godcmd] 因未设置口令，本次的临时口令为2630。
[INFO][2024-10-27 16:51:15][godcmd.py:210] - [Godcmd] inited
[INFO][2024-10-27 16:51:15][keyword.py:40] - [keyword] {}
[INFO][2024-10-27 16:51:15][keyword.py:42] - [keyword] inited.
[INFO][2024-10-27 16:51:15][linkai.py:35] - [LinkAI] inited, config={'group_app_map': {'测试群名1': 'default', '测试群名2': 'Kv2fXJcH'}, 'midjourney': {'enabled': False, 'auto_translate': True, 'img_proxy': True, 'max_tasks': 3, 'max_tasks_per_user': 1, 'use_image_create_prefix': True}, 'summary': {'enabled': False, 'group_enabled': True, 'max_file_size': 5000, 'type': ['FILE', 'SHARING']}}
[INFO][2024-10-27 16:51:15][role.py:69] - [Role] inited
[INFO][2024-10-27 16:51:15][dungeon.py:56] - [Dungeon] inited
[INFO][2024-10-27 16:51:15][hello.py:38] - [Hello] inited
[INFO][2024-10-27 16:51:15][finish.py:23] - [Finish] inited
[INFO][2024-10-27 16:51:55][wechat_channel.py:131] - Wechat login success, user_id: @ba63ae393c9e7be313242e27fe5445d7ea7eefb267862fd57a6c15f5a8d5c64d, nickname: 平
[INFO][2024-10-27 16:52:49][app.py:19] - signal 2 received, exiting...
[INFO][2024-10-27 16:52:49][config.py:237] - [Config] User datas saved.
[INFO][2024-10-27 16:52:49][app.py:19] - signal 2 received, exiting...
[INFO][2024-10-27 16:52:49][config.py:237] - [Config] User datas saved.
[INFO][2024-10-27 16:58:17][config.py:302] - [INIT] load config: {'channel_type': 'wx', 'model': 'coze', 'coze_api_base': 'https://api.coze.cn/open_api/v2', 'coze_api_key': 'pat*****hv8', 'coze_bot_id': '7430312631141318675', 'text_to_image': 'dall-e-2', 'voice_to_text': 'openai', 'text_to_voice': 'openai', 'proxy': '', 'hot_reload': False, 'single_chat_prefix': ['bot', '@bot'], 'single_chat_reply_prefix': '[bot] ', 'group_chat_prefix': ['@bot'], 'group_name_white_list': ['A7❤️进群看群公告', '诗词配音素材群'], 'image_create_prefix': ['画'], 'speech_recognition': True, 'group_speech_recognition': False, 'voice_reply_voice': False, 'conversation_max_tokens': 2500, 'expires_in_seconds': 3600, 'character_desc': '你是基于大语言模型的AI智能助手，旨在回答并解决人们的任何问题，并且可以使用多种语言与人交流。', 'temperature': 0.7, 'subscribe_msg': '感谢您的关注！\n这里是AI智能助手，可以自由对话。\n支持语音对话。\n支持图片输入。\n支持图片输出，画字开头的消息将按要求创作图片。\n支持tool、角色扮演和文字冒险等丰富的插件。\n输入{trigger_prefix}#help 查看详细指令。', 'use_linkai': False, 'linkai_api_key': '*****', 'linkai_app_code': ''}
[INFO][2024-10-27 16:58:17][config.py:226] - [Config] User datas loaded.
[INFO][2024-10-27 16:58:17][plugin_manager.py:50] - Loading plugins config...
[INFO][2024-10-27 16:58:17][plugin_manager.py:88] - Scaning plugins ...
[INFO][2024-10-27 16:58:17][plugin_manager.py:41] - Plugin Banwords_v1.0 registered, path=./plugins\banwords
[INFO][2024-10-27 16:58:17][plugin_manager.py:41] - Plugin BDunit_v0.1 registered, path=./plugins\bdunit
[INFO][2024-10-27 16:58:17][plugin_manager.py:41] - Plugin Dungeon_v1.0 registered, path=./plugins\dungeon
[INFO][2024-10-27 16:58:17][plugin_manager.py:41] - Plugin Finish_v1.0 registered, path=./plugins\finish
[INFO][2024-10-27 16:58:17][plugin_manager.py:41] - Plugin Godcmd_v1.0 registered, path=./plugins\godcmd
[INFO][2024-10-27 16:58:17][plugin_manager.py:41] - Plugin Hello_v0.1 registered, path=./plugins\hello
[INFO][2024-10-27 16:58:17][plugin_manager.py:41] - Plugin Keyword_v0.1 registered, path=./plugins\keyword
[INFO][2024-10-27 16:58:17][plugin_manager.py:41] - Plugin linkai_v0.1.0 registered, path=./plugins\linkai
[INFO][2024-10-27 16:58:17][plugin_manager.py:41] - Plugin Role_v1.0 registered, path=./plugins\role
[WARNING][2024-10-27 16:58:17][plugin_manager.py:113] - Failed to import plugin tool: No module named 'chatgpt_tool_hub'
[INFO][2024-10-27 16:58:17][godcmd.py:194] - [Godcmd] 因未设置口令，本次的临时口令为8401。
[INFO][2024-10-27 16:58:17][godcmd.py:210] - [Godcmd] inited
[INFO][2024-10-27 16:58:17][keyword.py:40] - [keyword] {}
[INFO][2024-10-27 16:58:17][keyword.py:42] - [keyword] inited.
[INFO][2024-10-27 16:58:17][linkai.py:35] - [LinkAI] inited, config={'group_app_map': {'测试群名1': 'default', '测试群名2': 'Kv2fXJcH'}, 'midjourney': {'enabled': False, 'auto_translate': True, 'img_proxy': True, 'max_tasks': 3, 'max_tasks_per_user': 1, 'use_image_create_prefix': True}, 'summary': {'enabled': False, 'group_enabled': True, 'max_file_size': 5000, 'type': ['FILE', 'SHARING']}}
[INFO][2024-10-27 16:58:17][role.py:69] - [Role] inited
[INFO][2024-10-27 16:58:17][dungeon.py:56] - [Dungeon] inited
[INFO][2024-10-27 16:58:17][hello.py:38] - [Hello] inited
[INFO][2024-10-27 16:58:17][finish.py:23] - [Finish] inited
[INFO][2024-10-27 16:58:43][wechat_channel.py:131] - Wechat login success, user_id: @da9d0ee265634de5e885fad9de82b25cf9a0f137dc5bc1d73dd632fa3bbe301d, nickname: bot
[INFO][2024-10-27 16:58:57][chat_channel.py:117] - [chat_channel]receive group at
[WARNING][2024-10-27 16:58:57][role.py:103] - 不支持的bot: coze
[INFO][2024-10-27 16:58:57][bridge.py:70] - create bot coze for chat
[INFO][2024-10-27 16:58:57][bytedance_coze_bot.py:26] - [COZE] query=厨神
[WARNING][2024-10-27 16:58:57][session_manager.py:72] - Exception when counting tokens precisely for prompt: No module named 'tiktoken'
[ERROR][2024-10-27 16:58:58][bytedance_coze_bot.py:33] - [COZE] reply error=[COZE] Error: 未具备相应权限，请查阅对应 API Token文档 如有问题请提交反馈
[INFO][2024-10-27 16:58:58][wechat_channel.py:217] - [WX] sendMsg=Reply(type=ERROR, content=[ERROR]
我暂时遇到了一些问题，请您稍后重试~), receiver=@@9a43858e0095af7e748853d7a925fb004abb5ab7fcdc7a1b335238dd9e849131
[INFO][2024-10-27 17:00:11][chat_channel.py:117] - [chat_channel]receive group at
[WARNING][2024-10-27 17:00:11][role.py:103] - 不支持的bot: coze
[INFO][2024-10-27 17:00:11][bytedance_coze_bot.py:26] - [COZE] query=桃花
[WARNING][2024-10-27 17:00:11][session_manager.py:72] - Exception when counting tokens precisely for prompt: No module named 'tiktoken'
[INFO][2024-10-27 17:00:23][wechat_channel.py:214] - [WX] sendMsg=Reply(type=TEXT, content=@小白菜白又白
为你搜索到短剧信息如下：
🎬 短剧名称：桃花马上请长缨
📁 短剧链接：https://pan.quark.cn/s/554768237f8e
🎬 短剧名称：《桃花马上请长缨》
📁 短剧链接：https://pan.quark.cn/s/3503d98661a1
🎬 短剧名称：13170-桃花医圣（177集）
📁 短剧链接：https://pan.quark.cn/s/8c04df77399b), receiver=@@9a43858e0095af7e748853d7a925fb004abb5ab7fcdc7a1b335238dd9e849131
[INFO][2024-10-27 17:00:43][chat_channel.py:117] - [chat_channel]receive group at
[WARNING][2024-10-27 17:00:43][role.py:103] - 不支持的bot: coze
[INFO][2024-10-27 17:00:43][bytedance_coze_bot.py:26] - [COZE] query=13111
[WARNING][2024-10-27 17:00:43][session_manager.py:72] - Exception when counting tokens precisely for prompt: No module named 'tiktoken'
[INFO][2024-10-27 17:00:54][wechat_channel.py:214] - [WX] sendMsg=Reply(type=TEXT, content=@小白菜白又白
为你搜索到短剧信息如下：
🎬 短剧名称：13111-玄学大佬她直播惊艳全球（47集）马铭婕
📁 短剧链接：https://pan.quark.cn/s/8313e05fc3a8), receiver=@@9a43858e0095af7e748853d7a925fb004abb5ab7fcdc7a1b335238dd9e849131
[INFO][2024-10-27 17:01:08][chat_channel.py:117] - [chat_channel]receive group at
[WARNING][2024-10-27 17:01:08][role.py:103] - 不支持的bot: coze
[INFO][2024-10-27 17:01:08][bytedance_coze_bot.py:26] - [COZE] query=13372
[WARNING][2024-10-27 17:01:08][session_manager.py:72] - Exception when counting tokens precisely for prompt: No module named 'tiktoken'
[INFO][2024-10-27 17:01:17][wechat_channel.py:214] - [WX] sendMsg=Reply(type=TEXT, content=@小白菜白又白
为你搜索到短剧信息如下：
🎬 短剧名称：13372-重生后我被京圈太子爷宠上天（78集）申浩男&钟熙
📁 短剧链接：https://pan.quark.cn/s/32b6a9e78daa), receiver=@@9a43858e0095af7e748853d7a925fb004abb5ab7fcdc7a1b335238dd9e849131
[INFO][2024-10-27 17:03:11][chat_channel.py:117] - [chat_channel]receive group at
[WARNING][2024-10-27 17:03:11][role.py:103] - 不支持的bot: coze
[INFO][2024-10-27 17:03:11][bytedance_coze_bot.py:26] - [COZE] query=13396
[WARNING][2024-10-27 17:03:11][session_manager.py:72] - Exception when counting tokens precisely for prompt: No module named 'tiktoken'
[ERROR][2024-10-27 17:03:26][chat_channel.py:291] - [chat_channel] sendMsg error: HTTPSConnectionPool(host='wx2.qq.com', port=443): Max retries exceeded with url: /cgi-bin/mmwebwx-bin/webwxsendmsg (Caused by ProxyError('Unable to connect to proxy', RemoteDisconnected('Remote end closed connection without response')))
[ERROR][2024-10-27 17:03:26][chat_channel.py:294] - HTTPSConnectionPool(host='wx2.qq.com', port=443): Max retries exceeded with url: /cgi-bin/mmwebwx-bin/webwxsendmsg (Caused by ProxyError('Unable to connect to proxy', RemoteDisconnected('Remote end closed connection without response')))
Traceback (most recent call last):
  File "C:\Users\Administrator\AppData\Local\Programs\Python\Python311\Lib\site-packages\urllib3\connectionpool.py", line 793, in urlopen
    response = self._make_request(
               ^^^^^^^^^^^^^^^^^^^
  File "C:\Users\Administrator\AppData\Local\Programs\Python\Python311\Lib\site-packages\urllib3\connectionpool.py", line 537, in _make_request
    response = conn.getresponse()
               ^^^^^^^^^^^^^^^^^^
  File "C:\Users\Administrator\AppData\Local\Programs\Python\Python311\Lib\site-packages\urllib3\connection.py", line 466, in getresponse
    httplib_response = super().getresponse()
                       ^^^^^^^^^^^^^^^^^^^^^
  File "C:\Users\Administrator\AppData\Local\Programs\Python\Python311\Lib\http\client.py", line 1395, in getresponse
    response.begin()
  File "C:\Users\Administrator\AppData\Local\Programs\Python\Python311\Lib\http\client.py", line 325, in begin
    version, status, reason = self._read_status()
                              ^^^^^^^^^^^^^^^^^^^
  File "C:\Users\Administrator\AppData\Local\Programs\Python\Python311\Lib\http\client.py", line 294, in _read_status
    raise RemoteDisconnected("Remote end closed connection without"
http.client.RemoteDisconnected: Remote end closed connection without response

The above exception was the direct cause of the following exception:

urllib3.exceptions.ProxyError: ('Unable to connect to proxy', RemoteDisconnected('Remote end closed connection without response'))

The above exception was the direct cause of the following exception:

Traceback (most recent call last):
  File "C:\Users\Administrator\AppData\Local\Programs\Python\Python311\Lib\site-packages\requests\adapters.py", line 486, in send
    resp = conn.urlopen(
           ^^^^^^^^^^^^^
  File "C:\Users\Administrator\AppData\Local\Programs\Python\Python311\Lib\site-packages\urllib3\connectionpool.py", line 847, in urlopen
    retries = retries.increment(
              ^^^^^^^^^^^^^^^^^^
  File "C:\Users\Administrator\AppData\Local\Programs\Python\Python311\Lib\site-packages\urllib3\util\retry.py", line 515, in increment
    raise MaxRetryError(_pool, url, reason) from reason  # type: ignore[arg-type]
    ^^^^^^^^^^^^^^^^^^^^^^^^^^^^^^^^^^^^^^^^^^^^^^^^^^^
urllib3.exceptions.MaxRetryError: HTTPSConnectionPool(host='wx2.qq.com', port=443): Max retries exceeded with url: /cgi-bin/mmwebwx-bin/webwxsendmsg (Caused by ProxyError('Unable to connect to proxy', RemoteDisconnected('Remote end closed connection without response')))

During handling of the above exception, another exception occurred:

Traceback (most recent call last):
  File "E:\code\cozewechat\chatgpt-on-wechat\channel\chat_channel.py", line 289, in _send
    self.send(reply, context)
  File "E:\code\cozewechat\chatgpt-on-wechat\channel\wechat\wechat_channel.py", line 213, in send
    itchat.send(reply.content, toUserName=receiver)
  File "E:\code\cozewechat\chatgpt-on-wechat\lib\itchat\components\messages.py", line 513, in send
    r = self.send_msg(msg, toUserName)
        ^^^^^^^^^^^^^^^^^^^^^^^^^^^^^^
  File "E:\code\cozewechat\chatgpt-on-wechat\lib\itchat\components\messages.py", line 283, in send_msg
    r = self.send_raw_msg(1, msg, toUserName)
        ^^^^^^^^^^^^^^^^^^^^^^^^^^^^^^^^^^^^^
  File "E:\code\cozewechat\chatgpt-on-wechat\lib\itchat\components\messages.py", line 277, in send_raw_msg
    r = self.s.post(url, headers=headers,
        ^^^^^^^^^^^^^^^^^^^^^^^^^^^^^^^^^
  File "C:\Users\Administrator\AppData\Local\Programs\Python\Python311\Lib\site-packages\requests\sessions.py", line 637, in post
    return self.request("POST", url, data=data, json=json, **kwargs)
           ^^^^^^^^^^^^^^^^^^^^^^^^^^^^^^^^^^^^^^^^^^^^^^^^^^^^^^^^^
  File "C:\Users\Administrator\AppData\Local\Programs\Python\Python311\Lib\site-packages\requests\sessions.py", line 589, in request
    resp = self.send(prep, **send_kwargs)
           ^^^^^^^^^^^^^^^^^^^^^^^^^^^^^^
  File "C:\Users\Administrator\AppData\Local\Programs\Python\Python311\Lib\site-packages\requests\sessions.py", line 703, in send
    r = adapter.send(request, **kwargs)
        ^^^^^^^^^^^^^^^^^^^^^^^^^^^^^^^
  File "C:\Users\Administrator\AppData\Local\Programs\Python\Python311\Lib\site-packages\requests\adapters.py", line 513, in send
    raise ProxyError(e, request=request)
requests.exceptions.ProxyError: HTTPSConnectionPool(host='wx2.qq.com', port=443): Max retries exceeded with url: /cgi-bin/mmwebwx-bin/webwxsendmsg (Caused by ProxyError('Unable to connect to proxy', RemoteDisconnected('Remote end closed connection without response')))
[INFO][2024-10-27 17:03:30][wechat_channel.py:214] - [WX] sendMsg=Reply(type=TEXT, content=@追剧小能手
为你搜索到短剧信息如下：
🎬 短剧名称：13396-离婚后她带崽嫁入豪门（80集）裴总第二部 许梦圆
📁 短剧链接：https://pan.quark.cn/s/147e167a158c), receiver=@@9a43858e0095af7e748853d7a925fb004abb5ab7fcdc7a1b335238dd9e849131
[INFO][2024-10-27 17:04:55][config.py:302] - [INIT] load config: {'channel_type': 'wx', 'model': 'coze', 'coze_api_base': 'https://api.coze.cn/open_api/v2', 'coze_api_key': 'pat*****hv8', 'coze_bot_id': '7430312631141318675', 'text_to_image': 'dall-e-2', 'voice_to_text': 'openai', 'text_to_voice': 'openai', 'proxy': '', 'hot_reload': False, 'single_chat_prefix': [], 'single_chat_reply_prefix': '[bot] ', 'group_chat_prefix': ['@bot'], 'group_name_white_list': ['A7❤️进群看群公告', '诗词配音素材群'], 'image_create_prefix': ['画'], 'speech_recognition': True, 'group_speech_recognition': False, 'voice_reply_voice': False, 'conversation_max_tokens': 2500, 'expires_in_seconds': 3600, 'character_desc': '你是基于大语言模型的AI智能助手，旨在回答并解决人们的任何问题，并且可以使用多种语言与人交流。', 'temperature': 0.7, 'subscribe_msg': '感谢您的关注！\n这里是AI智能助手，可以自由对话。\n支持语音对话。\n支持图片输入。\n支持图片输出，画字开头的消息将按要求创作图片。\n支持tool、角色扮演和文字冒险等丰富的插件。\n输入{trigger_prefix}#help 查看详细指令。', 'use_linkai': False, 'linkai_api_key': '*****', 'linkai_app_code': ''}
[INFO][2024-10-27 17:04:55][config.py:226] - [Config] User datas loaded.
[INFO][2024-10-27 17:04:55][plugin_manager.py:50] - Loading plugins config...
[INFO][2024-10-27 17:04:55][plugin_manager.py:88] - Scaning plugins ...
[INFO][2024-10-27 17:04:55][plugin_manager.py:41] - Plugin Banwords_v1.0 registered, path=./plugins\banwords
[INFO][2024-10-27 17:04:55][plugin_manager.py:41] - Plugin BDunit_v0.1 registered, path=./plugins\bdunit
[INFO][2024-10-27 17:04:55][plugin_manager.py:41] - Plugin Dungeon_v1.0 registered, path=./plugins\dungeon
[INFO][2024-10-27 17:04:55][plugin_manager.py:41] - Plugin Finish_v1.0 registered, path=./plugins\finish
[INFO][2024-10-27 17:04:55][plugin_manager.py:41] - Plugin Godcmd_v1.0 registered, path=./plugins\godcmd
[INFO][2024-10-27 17:04:55][plugin_manager.py:41] - Plugin Hello_v0.1 registered, path=./plugins\hello
[INFO][2024-10-27 17:04:55][plugin_manager.py:41] - Plugin Keyword_v0.1 registered, path=./plugins\keyword
[INFO][2024-10-27 17:04:55][plugin_manager.py:41] - Plugin linkai_v0.1.0 registered, path=./plugins\linkai
[INFO][2024-10-27 17:04:55][plugin_manager.py:41] - Plugin Role_v1.0 registered, path=./plugins\role
[WARNING][2024-10-27 17:04:55][plugin_manager.py:113] - Failed to import plugin tool: No module named 'chatgpt_tool_hub'
[INFO][2024-10-27 17:04:55][godcmd.py:194] - [Godcmd] 因未设置口令，本次的临时口令为5630。
[INFO][2024-10-27 17:04:55][godcmd.py:210] - [Godcmd] inited
[INFO][2024-10-27 17:04:55][keyword.py:40] - [keyword] {}
[INFO][2024-10-27 17:04:55][keyword.py:42] - [keyword] inited.
[INFO][2024-10-27 17:04:55][linkai.py:35] - [LinkAI] inited, config={'group_app_map': {'测试群名1': 'default', '测试群名2': 'Kv2fXJcH'}, 'midjourney': {'enabled': False, 'auto_translate': True, 'img_proxy': True, 'max_tasks': 3, 'max_tasks_per_user': 1, 'use_image_create_prefix': True}, 'summary': {'enabled': False, 'group_enabled': True, 'max_file_size': 5000, 'type': ['FILE', 'SHARING']}}
[INFO][2024-10-27 17:04:55][role.py:69] - [Role] inited
[INFO][2024-10-27 17:04:55][dungeon.py:56] - [Dungeon] inited
[INFO][2024-10-27 17:04:55][hello.py:38] - [Hello] inited
[INFO][2024-10-27 17:04:55][finish.py:23] - [Finish] inited
[INFO][2024-10-27 17:05:22][wechat_channel.py:131] - Wechat login success, user_id: @10b8bda211d91ce96962a757ae7d1831337751339a3da42c1d0f2ea4660a4b76, nickname: bot
[INFO][2024-10-27 17:05:37][chat_channel.py:117] - [chat_channel]receive group at
[WARNING][2024-10-27 17:05:37][role.py:103] - 不支持的bot: coze
[INFO][2024-10-27 17:05:37][bridge.py:70] - create bot coze for chat
[INFO][2024-10-27 17:05:37][bytedance_coze_bot.py:26] - [COZE] query=桃花
[WARNING][2024-10-27 17:05:37][session_manager.py:72] - Exception when counting tokens precisely for prompt: No module named 'tiktoken'
[ERROR][2024-10-27 17:05:52][chat_channel.py:291] - [chat_channel] sendMsg error: HTTPSConnectionPool(host='wx2.qq.com', port=443): Max retries exceeded with url: /cgi-bin/mmwebwx-bin/webwxsendmsg (Caused by ProxyError('Unable to connect to proxy', RemoteDisconnected('Remote end closed connection without response')))
[ERROR][2024-10-27 17:05:52][chat_channel.py:294] - HTTPSConnectionPool(host='wx2.qq.com', port=443): Max retries exceeded with url: /cgi-bin/mmwebwx-bin/webwxsendmsg (Caused by ProxyError('Unable to connect to proxy', RemoteDisconnected('Remote end closed connection without response')))
Traceback (most recent call last):
  File "C:\Users\Administrator\AppData\Local\Programs\Python\Python311\Lib\site-packages\urllib3\connectionpool.py", line 793, in urlopen
    response = self._make_request(
               ^^^^^^^^^^^^^^^^^^^
  File "C:\Users\Administrator\AppData\Local\Programs\Python\Python311\Lib\site-packages\urllib3\connectionpool.py", line 537, in _make_request
    response = conn.getresponse()
               ^^^^^^^^^^^^^^^^^^
  File "C:\Users\Administrator\AppData\Local\Programs\Python\Python311\Lib\site-packages\urllib3\connection.py", line 466, in getresponse
    httplib_response = super().getresponse()
                       ^^^^^^^^^^^^^^^^^^^^^
  File "C:\Users\Administrator\AppData\Local\Programs\Python\Python311\Lib\http\client.py", line 1395, in getresponse
    response.begin()
  File "C:\Users\Administrator\AppData\Local\Programs\Python\Python311\Lib\http\client.py", line 325, in begin
    version, status, reason = self._read_status()
                              ^^^^^^^^^^^^^^^^^^^
  File "C:\Users\Administrator\AppData\Local\Programs\Python\Python311\Lib\http\client.py", line 294, in _read_status
    raise RemoteDisconnected("Remote end closed connection without"
http.client.RemoteDisconnected: Remote end closed connection without response

The above exception was the direct cause of the following exception:

urllib3.exceptions.ProxyError: ('Unable to connect to proxy', RemoteDisconnected('Remote end closed connection without response'))

The above exception was the direct cause of the following exception:

Traceback (most recent call last):
  File "C:\Users\Administrator\AppData\Local\Programs\Python\Python311\Lib\site-packages\requests\adapters.py", line 486, in send
    resp = conn.urlopen(
           ^^^^^^^^^^^^^
  File "C:\Users\Administrator\AppData\Local\Programs\Python\Python311\Lib\site-packages\urllib3\connectionpool.py", line 847, in urlopen
    retries = retries.increment(
              ^^^^^^^^^^^^^^^^^^
  File "C:\Users\Administrator\AppData\Local\Programs\Python\Python311\Lib\site-packages\urllib3\util\retry.py", line 515, in increment
    raise MaxRetryError(_pool, url, reason) from reason  # type: ignore[arg-type]
    ^^^^^^^^^^^^^^^^^^^^^^^^^^^^^^^^^^^^^^^^^^^^^^^^^^^
urllib3.exceptions.MaxRetryError: HTTPSConnectionPool(host='wx2.qq.com', port=443): Max retries exceeded with url: /cgi-bin/mmwebwx-bin/webwxsendmsg (Caused by ProxyError('Unable to connect to proxy', RemoteDisconnected('Remote end closed connection without response')))

During handling of the above exception, another exception occurred:

Traceback (most recent call last):
  File "E:\code\cozewechat\chatgpt-on-wechat\channel\chat_channel.py", line 289, in _send
    self.send(reply, context)
  File "E:\code\cozewechat\chatgpt-on-wechat\channel\wechat\wechat_channel.py", line 213, in send
    itchat.send(reply.content, toUserName=receiver)
  File "E:\code\cozewechat\chatgpt-on-wechat\lib\itchat\components\messages.py", line 513, in send
    r = self.send_msg(msg, toUserName)
        ^^^^^^^^^^^^^^^^^^^^^^^^^^^^^^
  File "E:\code\cozewechat\chatgpt-on-wechat\lib\itchat\components\messages.py", line 283, in send_msg
    r = self.send_raw_msg(1, msg, toUserName)
        ^^^^^^^^^^^^^^^^^^^^^^^^^^^^^^^^^^^^^
  File "E:\code\cozewechat\chatgpt-on-wechat\lib\itchat\components\messages.py", line 277, in send_raw_msg
    r = self.s.post(url, headers=headers,
        ^^^^^^^^^^^^^^^^^^^^^^^^^^^^^^^^^
  File "C:\Users\Administrator\AppData\Local\Programs\Python\Python311\Lib\site-packages\requests\sessions.py", line 637, in post
    return self.request("POST", url, data=data, json=json, **kwargs)
           ^^^^^^^^^^^^^^^^^^^^^^^^^^^^^^^^^^^^^^^^^^^^^^^^^^^^^^^^^
  File "C:\Users\Administrator\AppData\Local\Programs\Python\Python311\Lib\site-packages\requests\sessions.py", line 589, in request
    resp = self.send(prep, **send_kwargs)
           ^^^^^^^^^^^^^^^^^^^^^^^^^^^^^^
  File "C:\Users\Administrator\AppData\Local\Programs\Python\Python311\Lib\site-packages\requests\sessions.py", line 703, in send
    r = adapter.send(request, **kwargs)
        ^^^^^^^^^^^^^^^^^^^^^^^^^^^^^^^
  File "C:\Users\Administrator\AppData\Local\Programs\Python\Python311\Lib\site-packages\requests\adapters.py", line 513, in send
    raise ProxyError(e, request=request)
requests.exceptions.ProxyError: HTTPSConnectionPool(host='wx2.qq.com', port=443): Max retries exceeded with url: /cgi-bin/mmwebwx-bin/webwxsendmsg (Caused by ProxyError('Unable to connect to proxy', RemoteDisconnected('Remote end closed connection without response')))
[INFO][2024-10-27 17:05:56][wechat_channel.py:214] - [WX] sendMsg=Reply(type=TEXT, content=@小白菜白又白
为你搜索到短剧信息如下：
🎬 短剧名称：桃花马上请长缨
📁 短剧链接：https://pan.quark.cn/s/554768237f8e
🎬 短剧名称：《桃花马上请长缨》
📁 短剧链接：https://pan.quark.cn/s/3503d98661a1
🎬 短剧名称：13170-桃花医圣（177集）
📁 短剧链接：https://pan.quark.cn/s/8c04df77399b), receiver=@@1f1933057247edc84193c05d6cd346ddb6b512892bd4942f5b88422c70cc5a53
[INFO][2024-10-27 17:08:04][app.py:19] - signal 2 received, exiting...
[INFO][2024-10-27 17:08:04][config.py:237] - [Config] User datas saved.
[INFO][2024-10-27 17:09:11][config.py:302] - [INIT] load config: {'channel_type': 'wx', 'model': 'coze', 'coze_api_base': 'https://api.coze.cn/open_api/v2', 'coze_api_key': 'pat*****hv8', 'coze_bot_id': '7430312631141318675', 'text_to_image': 'dall-e-2', 'voice_to_text': 'openai', 'text_to_voice': 'openai', 'proxy': '', 'hot_reload': False, 'single_chat_prefix': [], 'single_chat_reply_prefix': '[bot] ', 'group_chat_prefix': [], 'group_name_white_list': ['A7❤️进群看群公告', '诗词配音素材群'], 'image_create_prefix': ['画'], 'speech_recognition': True, 'group_speech_recognition': False, 'voice_reply_voice': False, 'conversation_max_tokens': 2500, 'expires_in_seconds': 3600, 'character_desc': '你是基于大语言模型的AI智能助手，旨在回答并解决人们的任何问题，并且可以使用多种语言与人交流。', 'temperature': 0.7, 'subscribe_msg': '感谢您的关注！\n这里是AI智能助手，可以自由对话。\n支持语音对话。\n支持图片输入。\n支持图片输出，画字开头的消息将按要求创作图片。\n支持tool、角色扮演和文字冒险等丰富的插件。\n输入{trigger_prefix}#help 查看详细指令。', 'use_linkai': False, 'linkai_api_key': '*****', 'linkai_app_code': ''}
[INFO][2024-10-27 17:09:11][config.py:226] - [Config] User datas loaded.
[INFO][2024-10-27 17:09:12][plugin_manager.py:50] - Loading plugins config...
[INFO][2024-10-27 17:09:12][plugin_manager.py:88] - Scaning plugins ...
[INFO][2024-10-27 17:09:12][plugin_manager.py:41] - Plugin Banwords_v1.0 registered, path=./plugins\banwords
[INFO][2024-10-27 17:09:12][plugin_manager.py:41] - Plugin BDunit_v0.1 registered, path=./plugins\bdunit
[INFO][2024-10-27 17:09:12][plugin_manager.py:41] - Plugin Dungeon_v1.0 registered, path=./plugins\dungeon
[INFO][2024-10-27 17:09:12][plugin_manager.py:41] - Plugin Finish_v1.0 registered, path=./plugins\finish
[INFO][2024-10-27 17:09:12][plugin_manager.py:41] - Plugin Godcmd_v1.0 registered, path=./plugins\godcmd
[INFO][2024-10-27 17:09:12][plugin_manager.py:41] - Plugin Hello_v0.1 registered, path=./plugins\hello
[INFO][2024-10-27 17:09:12][plugin_manager.py:41] - Plugin Keyword_v0.1 registered, path=./plugins\keyword
[INFO][2024-10-27 17:09:12][plugin_manager.py:41] - Plugin linkai_v0.1.0 registered, path=./plugins\linkai
[INFO][2024-10-27 17:09:12][plugin_manager.py:41] - Plugin Role_v1.0 registered, path=./plugins\role
[WARNING][2024-10-27 17:09:12][plugin_manager.py:113] - Failed to import plugin tool: No module named 'chatgpt_tool_hub'
[INFO][2024-10-27 17:09:12][godcmd.py:194] - [Godcmd] 因未设置口令，本次的临时口令为3061。
[INFO][2024-10-27 17:09:12][godcmd.py:210] - [Godcmd] inited
[INFO][2024-10-27 17:09:12][keyword.py:40] - [keyword] {}
[INFO][2024-10-27 17:09:12][keyword.py:42] - [keyword] inited.
[INFO][2024-10-27 17:09:12][linkai.py:35] - [LinkAI] inited, config={'group_app_map': {'测试群名1': 'default', '测试群名2': 'Kv2fXJcH'}, 'midjourney': {'enabled': False, 'auto_translate': True, 'img_proxy': True, 'max_tasks': 3, 'max_tasks_per_user': 1, 'use_image_create_prefix': True}, 'summary': {'enabled': False, 'group_enabled': True, 'max_file_size': 5000, 'type': ['FILE', 'SHARING']}}
[INFO][2024-10-27 17:09:12][role.py:69] - [Role] inited
[INFO][2024-10-27 17:09:12][dungeon.py:56] - [Dungeon] inited
[INFO][2024-10-27 17:09:12][hello.py:38] - [Hello] inited
[INFO][2024-10-27 17:09:12][finish.py:23] - [Finish] inited
[INFO][2024-10-27 17:09:37][wechat_channel.py:131] - Wechat login success, user_id: @aa4a0775c5bbc55d375557db8f4e18bc82e6d613907042730cc12dda3520c86c, nickname: bot
[INFO][2024-10-27 17:10:03][chat_channel.py:117] - [chat_channel]receive group at
[WARNING][2024-10-27 17:10:03][role.py:103] - 不支持的bot: coze
[INFO][2024-10-27 17:10:03][bridge.py:70] - create bot coze for chat
[INFO][2024-10-27 17:10:03][bytedance_coze_bot.py:26] - [COZE] query=桃花
[WARNING][2024-10-27 17:10:03][session_manager.py:72] - Exception when counting tokens precisely for prompt: No module named 'tiktoken'
[ERROR][2024-10-27 17:10:18][chat_channel.py:291] - [chat_channel] sendMsg error: HTTPSConnectionPool(host='wx2.qq.com', port=443): Max retries exceeded with url: /cgi-bin/mmwebwx-bin/webwxsendmsg (Caused by ProxyError('Unable to connect to proxy', RemoteDisconnected('Remote end closed connection without response')))
[ERROR][2024-10-27 17:10:18][chat_channel.py:294] - HTTPSConnectionPool(host='wx2.qq.com', port=443): Max retries exceeded with url: /cgi-bin/mmwebwx-bin/webwxsendmsg (Caused by ProxyError('Unable to connect to proxy', RemoteDisconnected('Remote end closed connection without response')))
Traceback (most recent call last):
  File "C:\Users\Administrator\AppData\Local\Programs\Python\Python311\Lib\site-packages\urllib3\connectionpool.py", line 793, in urlopen
    response = self._make_request(
               ^^^^^^^^^^^^^^^^^^^
  File "C:\Users\Administrator\AppData\Local\Programs\Python\Python311\Lib\site-packages\urllib3\connectionpool.py", line 537, in _make_request
    response = conn.getresponse()
               ^^^^^^^^^^^^^^^^^^
  File "C:\Users\Administrator\AppData\Local\Programs\Python\Python311\Lib\site-packages\urllib3\connection.py", line 466, in getresponse
    httplib_response = super().getresponse()
                       ^^^^^^^^^^^^^^^^^^^^^
  File "C:\Users\Administrator\AppData\Local\Programs\Python\Python311\Lib\http\client.py", line 1395, in getresponse
    response.begin()
  File "C:\Users\Administrator\AppData\Local\Programs\Python\Python311\Lib\http\client.py", line 325, in begin
    version, status, reason = self._read_status()
                              ^^^^^^^^^^^^^^^^^^^
  File "C:\Users\Administrator\AppData\Local\Programs\Python\Python311\Lib\http\client.py", line 294, in _read_status
    raise RemoteDisconnected("Remote end closed connection without"
http.client.RemoteDisconnected: Remote end closed connection without response

The above exception was the direct cause of the following exception:

urllib3.exceptions.ProxyError: ('Unable to connect to proxy', RemoteDisconnected('Remote end closed connection without response'))

The above exception was the direct cause of the following exception:

Traceback (most recent call last):
  File "C:\Users\Administrator\AppData\Local\Programs\Python\Python311\Lib\site-packages\requests\adapters.py", line 486, in send
    resp = conn.urlopen(
           ^^^^^^^^^^^^^
  File "C:\Users\Administrator\AppData\Local\Programs\Python\Python311\Lib\site-packages\urllib3\connectionpool.py", line 847, in urlopen
    retries = retries.increment(
              ^^^^^^^^^^^^^^^^^^
  File "C:\Users\Administrator\AppData\Local\Programs\Python\Python311\Lib\site-packages\urllib3\util\retry.py", line 515, in increment
    raise MaxRetryError(_pool, url, reason) from reason  # type: ignore[arg-type]
    ^^^^^^^^^^^^^^^^^^^^^^^^^^^^^^^^^^^^^^^^^^^^^^^^^^^
urllib3.exceptions.MaxRetryError: HTTPSConnectionPool(host='wx2.qq.com', port=443): Max retries exceeded with url: /cgi-bin/mmwebwx-bin/webwxsendmsg (Caused by ProxyError('Unable to connect to proxy', RemoteDisconnected('Remote end closed connection without response')))

During handling of the above exception, another exception occurred:

Traceback (most recent call last):
  File "E:\code\cozewechat\chatgpt-on-wechat\channel\chat_channel.py", line 289, in _send
    self.send(reply, context)
  File "E:\code\cozewechat\chatgpt-on-wechat\channel\wechat\wechat_channel.py", line 213, in send
    itchat.send(reply.content, toUserName=receiver)
  File "E:\code\cozewechat\chatgpt-on-wechat\lib\itchat\components\messages.py", line 513, in send
    r = self.send_msg(msg, toUserName)
        ^^^^^^^^^^^^^^^^^^^^^^^^^^^^^^
  File "E:\code\cozewechat\chatgpt-on-wechat\lib\itchat\components\messages.py", line 283, in send_msg
    r = self.send_raw_msg(1, msg, toUserName)
        ^^^^^^^^^^^^^^^^^^^^^^^^^^^^^^^^^^^^^
  File "E:\code\cozewechat\chatgpt-on-wechat\lib\itchat\components\messages.py", line 277, in send_raw_msg
    r = self.s.post(url, headers=headers,
        ^^^^^^^^^^^^^^^^^^^^^^^^^^^^^^^^^
  File "C:\Users\Administrator\AppData\Local\Programs\Python\Python311\Lib\site-packages\requests\sessions.py", line 637, in post
    return self.request("POST", url, data=data, json=json, **kwargs)
           ^^^^^^^^^^^^^^^^^^^^^^^^^^^^^^^^^^^^^^^^^^^^^^^^^^^^^^^^^
  File "C:\Users\Administrator\AppData\Local\Programs\Python\Python311\Lib\site-packages\requests\sessions.py", line 589, in request
    resp = self.send(prep, **send_kwargs)
           ^^^^^^^^^^^^^^^^^^^^^^^^^^^^^^
  File "C:\Users\Administrator\AppData\Local\Programs\Python\Python311\Lib\site-packages\requests\sessions.py", line 703, in send
    r = adapter.send(request, **kwargs)
        ^^^^^^^^^^^^^^^^^^^^^^^^^^^^^^^
  File "C:\Users\Administrator\AppData\Local\Programs\Python\Python311\Lib\site-packages\requests\adapters.py", line 513, in send
    raise ProxyError(e, request=request)
requests.exceptions.ProxyError: HTTPSConnectionPool(host='wx2.qq.com', port=443): Max retries exceeded with url: /cgi-bin/mmwebwx-bin/webwxsendmsg (Caused by ProxyError('Unable to connect to proxy', RemoteDisconnected('Remote end closed connection without response')))
[INFO][2024-10-27 17:10:22][wechat_channel.py:214] - [WX] sendMsg=Reply(type=TEXT, content=@小白菜白又白
为你搜索到短剧信息如下：
🎬 短剧名称：桃花马上请长缨
📁 短剧链接：https://pan.quark.cn/s/554768237f8e
🎬 短剧名称：《桃花马上请长缨》
📁 短剧链接：https://pan.quark.cn/s/3503d98661a1
🎬 短剧名称：13170-桃花医圣（177集）
📁 短剧链接：https://pan.quark.cn/s/8c04df77399b), receiver=@@1aad461a17569579f97fa76b70eaf776bf5080dd5ff090c982569d4895692b05
[INFO][2024-10-27 17:11:34][app.py:19] - signal 2 received, exiting...
[INFO][2024-10-27 17:11:34][config.py:237] - [Config] User datas saved.
[INFO][2024-10-27 17:20:01][config.py:302] - [INIT] load config: {'channel_type': 'wx', 'model': 'coze', 'coze_api_base': 'https://api.coze.cn/open_api/v2', 'coze_api_key': 'pat*****hv8', 'coze_bot_id': '7430312631141318675', 'text_to_image': 'dall-e-2', 'voice_to_text': 'openai', 'text_to_voice': 'openai', 'proxy': '', 'hot_reload': False, 'single_chat_prefix': [], 'single_chat_reply_prefix': '[bot] ', 'group_chat_prefix': ['搜'], 'group_name_white_list': ['A7❤️进群看群公告', '诗词配音素材群', 'A6❤️短剧看群公告'], 'image_create_prefix': ['画'], 'speech_recognition': True, 'group_speech_recognition': False, 'voice_reply_voice': False, 'conversation_max_tokens': 2500, 'expires_in_seconds': 3600, 'character_desc': '你是基于大语言模型的AI智能助手，旨在回答并解决人们的任何问题，并且可以使用多种语言与人交流。', 'temperature': 0.7, 'subscribe_msg': '感谢您的关注！\n这里是AI智能助手，可以自由对话。\n支持语音对话。\n支持图片输入。\n支持图片输出，画字开头的消息将按要求创作图片。\n支持tool、角色扮演和文字冒险等丰富的插件。\n输入{trigger_prefix}#help 查看详细指令。', 'use_linkai': False, 'linkai_api_key': '*****', 'linkai_app_code': ''}
[INFO][2024-10-27 17:20:01][config.py:226] - [Config] User datas loaded.
[INFO][2024-10-27 17:20:01][plugin_manager.py:50] - Loading plugins config...
[INFO][2024-10-27 17:20:01][plugin_manager.py:88] - Scaning plugins ...
[INFO][2024-10-27 17:20:01][plugin_manager.py:41] - Plugin Banwords_v1.0 registered, path=./plugins\banwords
[INFO][2024-10-27 17:20:01][plugin_manager.py:41] - Plugin BDunit_v0.1 registered, path=./plugins\bdunit
[INFO][2024-10-27 17:20:01][plugin_manager.py:41] - Plugin Dungeon_v1.0 registered, path=./plugins\dungeon
[INFO][2024-10-27 17:20:01][plugin_manager.py:41] - Plugin Finish_v1.0 registered, path=./plugins\finish
[INFO][2024-10-27 17:20:01][plugin_manager.py:41] - Plugin Godcmd_v1.0 registered, path=./plugins\godcmd
[INFO][2024-10-27 17:20:01][plugin_manager.py:41] - Plugin Hello_v0.1 registered, path=./plugins\hello
[INFO][2024-10-27 17:20:01][plugin_manager.py:41] - Plugin Keyword_v0.1 registered, path=./plugins\keyword
[INFO][2024-10-27 17:20:01][plugin_manager.py:41] - Plugin linkai_v0.1.0 registered, path=./plugins\linkai
[INFO][2024-10-27 17:20:01][plugin_manager.py:41] - Plugin Role_v1.0 registered, path=./plugins\role
[WARNING][2024-10-27 17:20:01][plugin_manager.py:113] - Failed to import plugin tool: No module named 'chatgpt_tool_hub'
[INFO][2024-10-27 17:20:01][godcmd.py:194] - [Godcmd] 因未设置口令，本次的临时口令为6735。
[INFO][2024-10-27 17:20:01][godcmd.py:210] - [Godcmd] inited
[INFO][2024-10-27 17:20:01][keyword.py:40] - [keyword] {}
[INFO][2024-10-27 17:20:01][keyword.py:42] - [keyword] inited.
[INFO][2024-10-27 17:20:01][linkai.py:35] - [LinkAI] inited, config={'group_app_map': {'测试群名1': 'default', '测试群名2': 'Kv2fXJcH'}, 'midjourney': {'enabled': False, 'auto_translate': True, 'img_proxy': True, 'max_tasks': 3, 'max_tasks_per_user': 1, 'use_image_create_prefix': True}, 'summary': {'enabled': False, 'group_enabled': True, 'max_file_size': 5000, 'type': ['FILE', 'SHARING']}}
[INFO][2024-10-27 17:20:01][role.py:69] - [Role] inited
[INFO][2024-10-27 17:20:01][dungeon.py:56] - [Dungeon] inited
[INFO][2024-10-27 17:20:01][hello.py:38] - [Hello] inited
[INFO][2024-10-27 17:20:01][finish.py:23] - [Finish] inited
[INFO][2024-10-27 17:20:27][wechat_channel.py:131] - Wechat login success, user_id: @70ae507ae615c1bde8a095378a091c2f2cd4f19f33172741f29fab1ffeba82ca, nickname: bot
[WARNING][2024-10-27 17:20:54][role.py:103] - 不支持的bot: coze
[INFO][2024-10-27 17:20:54][bridge.py:70] - create bot coze for chat
[INFO][2024-10-27 17:20:54][bytedance_coze_bot.py:26] - [COZE] query=桃花马上请长
[WARNING][2024-10-27 17:20:57][chat_gpt_session.py:86] - num_tokens_from_messages() is not implemented for model coze. Returning num tokens assuming gpt-3.5-turbo.
[INFO][2024-10-27 17:21:07][wechat_channel.py:214] - [WX] sendMsg=Reply(type=TEXT, content=@小白菜白又白
为你搜索到短剧信息如下：
🎬 短剧名称：桃花马上请长缨
📁 短剧链接：https://pan.quark.cn/s/554768237f8e
🎬 短剧名称：《桃花马上请长缨》
📁 短剧链接：https://pan.quark.cn/s/3503d98661a1), receiver=@@bc2ae7d138f4a7a68e709adacba031c5cbec33f36e39e8e6c6c3289b39451d3b
[WARNING][2024-10-27 17:21:38][role.py:103] - 不支持的bot: coze
[INFO][2024-10-27 17:21:38][bytedance_coze_bot.py:26] - [COZE] query=13111
[WARNING][2024-10-27 17:21:38][chat_gpt_session.py:86] - num_tokens_from_messages() is not implemented for model coze. Returning num tokens assuming gpt-3.5-turbo.
[INFO][2024-10-27 17:21:46][wechat_channel.py:214] - [WX] sendMsg=Reply(type=TEXT, content=@小白菜白又白
为你搜索到短剧信息如下：
🎬 短剧名称：13111-玄学大佬她直播惊艳全球（47集）马铭婕
📁 短剧链接：https://pan.quark.cn/s/8313e05fc3a8), receiver=@@bc2ae7d138f4a7a68e709adacba031c5cbec33f36e39e8e6c6c3289b39451d3b
[WARNING][2024-10-27 17:22:27][role.py:103] - 不支持的bot: coze
[INFO][2024-10-27 17:22:27][bytedance_coze_bot.py:26] - [COZE] query=13111
[WARNING][2024-10-27 17:22:27][chat_gpt_session.py:86] - num_tokens_from_messages() is not implemented for model coze. Returning num tokens assuming gpt-3.5-turbo.
[INFO][2024-10-27 17:22:39][wechat_channel.py:214] - [WX] sendMsg=Reply(type=TEXT, content=@小白菜白又白
为你搜索到短剧信息如下：
🎬 短剧名称：13111-玄学大佬她直播惊艳全球（47集）马铭婕
📁 短剧链接：https://pan.quark.cn/s/8313e05fc3a8), receiver=@@0ab640aff7677190e8e759e59df1e53e5433dff06b16da3cb307af15c3eec707
[WARNING][2024-10-27 17:26:01][role.py:103] - 不支持的bot: coze
[INFO][2024-10-27 17:26:01][bytedance_coze_bot.py:26] - [COZE] query=13111
[WARNING][2024-10-27 17:26:01][chat_gpt_session.py:86] - num_tokens_from_messages() is not implemented for model coze. Returning num tokens assuming gpt-3.5-turbo.
[INFO][2024-10-27 17:26:11][wechat_channel.py:214] - [WX] sendMsg=Reply(type=TEXT, content=@追剧小能手
为你搜索到短剧信息如下：
🎬 短剧名称：13111-玄学大佬她直播惊艳全球（47集）马铭婕
📁 短剧链接：https://pan.quark.cn/s/8313e05fc3a8), receiver=@@bc2ae7d138f4a7a68e709adacba031c5cbec33f36e39e8e6c6c3289b39451d3b
[WARNING][2024-10-27 17:27:05][role.py:103] - 不支持的bot: coze
[INFO][2024-10-27 17:27:05][bytedance_coze_bot.py:26] - [COZE] query=弄春风
[WARNING][2024-10-27 17:27:05][chat_gpt_session.py:86] - num_tokens_from_messages() is not implemented for model coze. Returning num tokens assuming gpt-3.5-turbo.
[INFO][2024-10-27 17:27:12][wechat_channel.py:214] - [WX] sendMsg=Reply(type=TEXT, content=@追剧小能手
为你搜索到短剧信息如下：
🎬 短剧名称：13405-弄春风（99集）张楚萱
📁 短剧链接：https://pan.quark.cn/s/0c6aabbffce0), receiver=@@bc2ae7d138f4a7a68e709adacba031c5cbec33f36e39e8e6c6c3289b39451d3b
[INFO][2024-10-27 17:28:04][chat_channel.py:117] - [chat_channel]receive group at
[WARNING][2024-10-27 17:28:05][role.py:103] - 不支持的bot: coze
[INFO][2024-10-27 17:28:05][bytedance_coze_bot.py:26] - [COZE] query=13391
[WARNING][2024-10-27 17:28:05][chat_gpt_session.py:86] - num_tokens_from_messages() is not implemented for model coze. Returning num tokens assuming gpt-3.5-turbo.
[ERROR][2024-10-27 17:28:18][chat_channel.py:291] - [chat_channel] sendMsg error: HTTPSConnectionPool(host='wx2.qq.com', port=443): Max retries exceeded with url: /cgi-bin/mmwebwx-bin/webwxsendmsg (Caused by ProxyError('Unable to connect to proxy', RemoteDisconnected('Remote end closed connection without response')))
[ERROR][2024-10-27 17:28:18][chat_channel.py:294] - HTTPSConnectionPool(host='wx2.qq.com', port=443): Max retries exceeded with url: /cgi-bin/mmwebwx-bin/webwxsendmsg (Caused by ProxyError('Unable to connect to proxy', RemoteDisconnected('Remote end closed connection without response')))
Traceback (most recent call last):
  File "C:\Users\Administrator\AppData\Local\Programs\Python\Python311\Lib\site-packages\urllib3\connectionpool.py", line 793, in urlopen
    response = self._make_request(
               ^^^^^^^^^^^^^^^^^^^
  File "C:\Users\Administrator\AppData\Local\Programs\Python\Python311\Lib\site-packages\urllib3\connectionpool.py", line 537, in _make_request
    response = conn.getresponse()
               ^^^^^^^^^^^^^^^^^^
  File "C:\Users\Administrator\AppData\Local\Programs\Python\Python311\Lib\site-packages\urllib3\connection.py", line 466, in getresponse
    httplib_response = super().getresponse()
                       ^^^^^^^^^^^^^^^^^^^^^
  File "C:\Users\Administrator\AppData\Local\Programs\Python\Python311\Lib\http\client.py", line 1395, in getresponse
    response.begin()
  File "C:\Users\Administrator\AppData\Local\Programs\Python\Python311\Lib\http\client.py", line 325, in begin
    version, status, reason = self._read_status()
                              ^^^^^^^^^^^^^^^^^^^
  File "C:\Users\Administrator\AppData\Local\Programs\Python\Python311\Lib\http\client.py", line 294, in _read_status
    raise RemoteDisconnected("Remote end closed connection without"
http.client.RemoteDisconnected: Remote end closed connection without response

The above exception was the direct cause of the following exception:

urllib3.exceptions.ProxyError: ('Unable to connect to proxy', RemoteDisconnected('Remote end closed connection without response'))

The above exception was the direct cause of the following exception:

Traceback (most recent call last):
  File "C:\Users\Administrator\AppData\Local\Programs\Python\Python311\Lib\site-packages\requests\adapters.py", line 486, in send
    resp = conn.urlopen(
           ^^^^^^^^^^^^^
  File "C:\Users\Administrator\AppData\Local\Programs\Python\Python311\Lib\site-packages\urllib3\connectionpool.py", line 847, in urlopen
    retries = retries.increment(
              ^^^^^^^^^^^^^^^^^^
  File "C:\Users\Administrator\AppData\Local\Programs\Python\Python311\Lib\site-packages\urllib3\util\retry.py", line 515, in increment
    raise MaxRetryError(_pool, url, reason) from reason  # type: ignore[arg-type]
    ^^^^^^^^^^^^^^^^^^^^^^^^^^^^^^^^^^^^^^^^^^^^^^^^^^^
urllib3.exceptions.MaxRetryError: HTTPSConnectionPool(host='wx2.qq.com', port=443): Max retries exceeded with url: /cgi-bin/mmwebwx-bin/webwxsendmsg (Caused by ProxyError('Unable to connect to proxy', RemoteDisconnected('Remote end closed connection without response')))

During handling of the above exception, another exception occurred:

Traceback (most recent call last):
  File "E:\code\cozewechat\chatgpt-on-wechat\channel\chat_channel.py", line 289, in _send
    self.send(reply, context)
  File "E:\code\cozewechat\chatgpt-on-wechat\channel\wechat\wechat_channel.py", line 213, in send
    itchat.send(reply.content, toUserName=receiver)
  File "E:\code\cozewechat\chatgpt-on-wechat\lib\itchat\components\messages.py", line 513, in send
    r = self.send_msg(msg, toUserName)
        ^^^^^^^^^^^^^^^^^^^^^^^^^^^^^^
  File "E:\code\cozewechat\chatgpt-on-wechat\lib\itchat\components\messages.py", line 283, in send_msg
    r = self.send_raw_msg(1, msg, toUserName)
        ^^^^^^^^^^^^^^^^^^^^^^^^^^^^^^^^^^^^^
  File "E:\code\cozewechat\chatgpt-on-wechat\lib\itchat\components\messages.py", line 277, in send_raw_msg
    r = self.s.post(url, headers=headers,
        ^^^^^^^^^^^^^^^^^^^^^^^^^^^^^^^^^
  File "C:\Users\Administrator\AppData\Local\Programs\Python\Python311\Lib\site-packages\requests\sessions.py", line 637, in post
    return self.request("POST", url, data=data, json=json, **kwargs)
           ^^^^^^^^^^^^^^^^^^^^^^^^^^^^^^^^^^^^^^^^^^^^^^^^^^^^^^^^^
  File "C:\Users\Administrator\AppData\Local\Programs\Python\Python311\Lib\site-packages\requests\sessions.py", line 589, in request
    resp = self.send(prep, **send_kwargs)
           ^^^^^^^^^^^^^^^^^^^^^^^^^^^^^^
  File "C:\Users\Administrator\AppData\Local\Programs\Python\Python311\Lib\site-packages\requests\sessions.py", line 703, in send
    r = adapter.send(request, **kwargs)
        ^^^^^^^^^^^^^^^^^^^^^^^^^^^^^^^
  File "C:\Users\Administrator\AppData\Local\Programs\Python\Python311\Lib\site-packages\requests\adapters.py", line 513, in send
    raise ProxyError(e, request=request)
requests.exceptions.ProxyError: HTTPSConnectionPool(host='wx2.qq.com', port=443): Max retries exceeded with url: /cgi-bin/mmwebwx-bin/webwxsendmsg (Caused by ProxyError('Unable to connect to proxy', RemoteDisconnected('Remote end closed connection without response')))
[INFO][2024-10-27 17:28:22][wechat_channel.py:214] - [WX] sendMsg=Reply(type=TEXT, content=@追剧小能手
为你搜索到短剧信息如下：
🎬 短剧名称：13391-今日天晴宜爱你（77集）朱一未&白昕怡
📁 短剧链接：https://pan.quark.cn/s/5eea03ee8766), receiver=@@bc2ae7d138f4a7a68e709adacba031c5cbec33f36e39e8e6c6c3289b39451d3b
[INFO][2024-10-27 17:40:43][bytedance_coze_bot.py:26] - [COZE] query=请你随机使用一种风格说一句问候语来欢迎新用户"爱人、不离15568111187"加入群聊。
[WARNING][2024-10-27 17:40:43][chat_gpt_session.py:86] - num_tokens_from_messages() is not implemented for model coze. Returning num tokens assuming gpt-3.5-turbo.
[ERROR][2024-10-27 17:40:58][chat_channel.py:291] - [chat_channel] sendMsg error: HTTPSConnectionPool(host='wx2.qq.com', port=443): Max retries exceeded with url: /cgi-bin/mmwebwx-bin/webwxsendmsg (Caused by ProxyError('Unable to connect to proxy', RemoteDisconnected('Remote end closed connection without response')))
[ERROR][2024-10-27 17:40:58][chat_channel.py:294] - HTTPSConnectionPool(host='wx2.qq.com', port=443): Max retries exceeded with url: /cgi-bin/mmwebwx-bin/webwxsendmsg (Caused by ProxyError('Unable to connect to proxy', RemoteDisconnected('Remote end closed connection without response')))
Traceback (most recent call last):
  File "C:\Users\Administrator\AppData\Local\Programs\Python\Python311\Lib\site-packages\urllib3\connectionpool.py", line 793, in urlopen
    response = self._make_request(
               ^^^^^^^^^^^^^^^^^^^
  File "C:\Users\Administrator\AppData\Local\Programs\Python\Python311\Lib\site-packages\urllib3\connectionpool.py", line 537, in _make_request
    response = conn.getresponse()
               ^^^^^^^^^^^^^^^^^^
  File "C:\Users\Administrator\AppData\Local\Programs\Python\Python311\Lib\site-packages\urllib3\connection.py", line 466, in getresponse
    httplib_response = super().getresponse()
                       ^^^^^^^^^^^^^^^^^^^^^
  File "C:\Users\Administrator\AppData\Local\Programs\Python\Python311\Lib\http\client.py", line 1395, in getresponse
    response.begin()
  File "C:\Users\Administrator\AppData\Local\Programs\Python\Python311\Lib\http\client.py", line 325, in begin
    version, status, reason = self._read_status()
                              ^^^^^^^^^^^^^^^^^^^
  File "C:\Users\Administrator\AppData\Local\Programs\Python\Python311\Lib\http\client.py", line 294, in _read_status
    raise RemoteDisconnected("Remote end closed connection without"
http.client.RemoteDisconnected: Remote end closed connection without response

The above exception was the direct cause of the following exception:

urllib3.exceptions.ProxyError: ('Unable to connect to proxy', RemoteDisconnected('Remote end closed connection without response'))

The above exception was the direct cause of the following exception:

Traceback (most recent call last):
  File "C:\Users\Administrator\AppData\Local\Programs\Python\Python311\Lib\site-packages\requests\adapters.py", line 486, in send
    resp = conn.urlopen(
           ^^^^^^^^^^^^^
  File "C:\Users\Administrator\AppData\Local\Programs\Python\Python311\Lib\site-packages\urllib3\connectionpool.py", line 847, in urlopen
    retries = retries.increment(
              ^^^^^^^^^^^^^^^^^^
  File "C:\Users\Administrator\AppData\Local\Programs\Python\Python311\Lib\site-packages\urllib3\util\retry.py", line 515, in increment
    raise MaxRetryError(_pool, url, reason) from reason  # type: ignore[arg-type]
    ^^^^^^^^^^^^^^^^^^^^^^^^^^^^^^^^^^^^^^^^^^^^^^^^^^^
urllib3.exceptions.MaxRetryError: HTTPSConnectionPool(host='wx2.qq.com', port=443): Max retries exceeded with url: /cgi-bin/mmwebwx-bin/webwxsendmsg (Caused by ProxyError('Unable to connect to proxy', RemoteDisconnected('Remote end closed connection without response')))

During handling of the above exception, another exception occurred:

Traceback (most recent call last):
  File "E:\code\cozewechat\chatgpt-on-wechat\channel\chat_channel.py", line 289, in _send
    self.send(reply, context)
  File "E:\code\cozewechat\chatgpt-on-wechat\channel\wechat\wechat_channel.py", line 213, in send
    itchat.send(reply.content, toUserName=receiver)
  File "E:\code\cozewechat\chatgpt-on-wechat\lib\itchat\components\messages.py", line 513, in send
    r = self.send_msg(msg, toUserName)
        ^^^^^^^^^^^^^^^^^^^^^^^^^^^^^^
  File "E:\code\cozewechat\chatgpt-on-wechat\lib\itchat\components\messages.py", line 283, in send_msg
    r = self.send_raw_msg(1, msg, toUserName)
        ^^^^^^^^^^^^^^^^^^^^^^^^^^^^^^^^^^^^^
  File "E:\code\cozewechat\chatgpt-on-wechat\lib\itchat\components\messages.py", line 277, in send_raw_msg
    r = self.s.post(url, headers=headers,
        ^^^^^^^^^^^^^^^^^^^^^^^^^^^^^^^^^
  File "C:\Users\Administrator\AppData\Local\Programs\Python\Python311\Lib\site-packages\requests\sessions.py", line 637, in post
    return self.request("POST", url, data=data, json=json, **kwargs)
           ^^^^^^^^^^^^^^^^^^^^^^^^^^^^^^^^^^^^^^^^^^^^^^^^^^^^^^^^^
  File "C:\Users\Administrator\AppData\Local\Programs\Python\Python311\Lib\site-packages\requests\sessions.py", line 589, in request
    resp = self.send(prep, **send_kwargs)
           ^^^^^^^^^^^^^^^^^^^^^^^^^^^^^^
  File "C:\Users\Administrator\AppData\Local\Programs\Python\Python311\Lib\site-packages\requests\sessions.py", line 703, in send
    r = adapter.send(request, **kwargs)
        ^^^^^^^^^^^^^^^^^^^^^^^^^^^^^^^
  File "C:\Users\Administrator\AppData\Local\Programs\Python\Python311\Lib\site-packages\requests\adapters.py", line 513, in send
    raise ProxyError(e, request=request)
requests.exceptions.ProxyError: HTTPSConnectionPool(host='wx2.qq.com', port=443): Max retries exceeded with url: /cgi-bin/mmwebwx-bin/webwxsendmsg (Caused by ProxyError('Unable to connect to proxy', RemoteDisconnected('Remote end closed connection without response')))
[INFO][2024-10-27 17:41:02][wechat_channel.py:214] - [WX] sendMsg=Reply(type=TEXT, content=@爱人、不离15568111187
关键词错误，请重新输入。), receiver=@@0ab640aff7677190e8e759e59df1e53e5433dff06b16da3cb307af15c3eec707
[INFO][2024-10-27 17:41:28][chat_channel.py:117] - [chat_channel]receive group at
[WARNING][2024-10-27 17:41:28][role.py:103] - 不支持的bot: coze
[INFO][2024-10-27 17:41:28][bytedance_coze_bot.py:26] - [COZE] query=13305
[WARNING][2024-10-27 17:41:28][chat_gpt_session.py:86] - num_tokens_from_messages() is not implemented for model coze. Returning num tokens assuming gpt-3.5-turbo.
[INFO][2024-10-27 17:41:39][wechat_channel.py:214] - [WX] sendMsg=Reply(type=TEXT, content=@小白菜白又白
为你搜索到短剧信息如下：
🎬 短剧名称：13305-我叫苏妲己（73集）
📁 短剧链接：https://pan.quark.cn/s/0ccb38527d55), receiver=@@0ab640aff7677190e8e759e59df1e53e5433dff06b16da3cb307af15c3eec707
[INFO][2024-10-27 17:47:45][bytedance_coze_bot.py:26] - [COZE] query=请你随机使用一种风格说一句问候语来欢迎新用户"范"加入群聊。
[WARNING][2024-10-27 17:47:45][chat_gpt_session.py:86] - num_tokens_from_messages() is not implemented for model coze. Returning num tokens assuming gpt-3.5-turbo.
[INFO][2024-10-27 17:47:52][wechat_channel.py:214] - [WX] sendMsg=Reply(type=TEXT, content=@范
嗨，范！欢迎加入群聊呀，就像星星落入了银河，你这个新成员的加入让咱们这个小群更加闪耀啦！), receiver=@@0ab640aff7677190e8e759e59df1e53e5433dff06b16da3cb307af15c3eec707
[WARNING][2024-10-27 17:49:16][role.py:103] - 不支持的bot: coze
[INFO][2024-10-27 17:49:16][bytedance_coze_bot.py:26] - [COZE] query=13279
[WARNING][2024-10-27 17:49:16][chat_gpt_session.py:86] - num_tokens_from_messages() is not implemented for model coze. Returning num tokens assuming gpt-3.5-turbo.
[INFO][2024-10-27 17:49:25][wechat_channel.py:214] - [WX] sendMsg=Reply(type=TEXT, content=@找剧小助理
为你搜索到短剧信息如下：
🎬 短剧名称：13279-被偷听心声后，豪门全家追着我宠（50集）
📁 短剧链接：https://pan.quark.cn/s/9ac1877d2aa4), receiver=@@0ab640aff7677190e8e759e59df1e53e5433dff06b16da3cb307af15c3eec707
[WARNING][2024-10-27 17:49:41][role.py:103] - 不支持的bot: coze
[INFO][2024-10-27 17:49:41][bytedance_coze_bot.py:26] - [COZE] query=13111
[WARNING][2024-10-27 17:49:41][chat_gpt_session.py:86] - num_tokens_from_messages() is not implemented for model coze. Returning num tokens assuming gpt-3.5-turbo.
[INFO][2024-10-27 17:49:48][wechat_channel.py:214] - [WX] sendMsg=Reply(type=TEXT, content=@一壶一茶🍵
为你搜索到短剧信息如下：
🎬 短剧名称：13111-玄学大佬她直播惊艳全球（47集）马铭婕
📁 短剧链接：https://pan.quark.cn/s/8313e05fc3a8), receiver=@@0ab640aff7677190e8e759e59df1e53e5433dff06b16da3cb307af15c3eec707
[ERROR][2024-10-27 19:06:36][app.py:66] - App startup failed!
[ERROR][2024-10-27 19:06:36][app.py:67] - key plugins not in available_setting
Traceback (most recent call last):
  File "E:\code\cozewechat\chatgpt-on-wechat\app.py", line 46, in run
    load_config()
  File "E:\code\cozewechat\chatgpt-on-wechat\config.py", line 280, in load_config
    config = Config(json.loads(config_str))
             ^^^^^^^^^^^^^^^^^^^^^^^^^^^^^^
  File "E:\code\cozewechat\chatgpt-on-wechat\config.py", line 194, in __init__
    self[k] = v
    ~~~~^^^
  File "E:\code\cozewechat\chatgpt-on-wechat\config.py", line 205, in __setitem__
    raise Exception("key {} not in available_setting".format(key))
Exception: key plugins not in available_setting
[INFO][2024-10-27 19:13:16][config.py:302] - [INIT] load config: {'channel_type': 'wx', 'model': 'coze', 'coze_api_base': 'https://api.coze.cn/open_api/v2', 'coze_api_key': 'pat*****hv8', 'coze_bot_id': '7430389582765555750', 'text_to_image': 'dall-e-2', 'voice_to_text': 'openai', 'text_to_voice': 'openai', 'proxy': '', 'hot_reload': False, 'single_chat_prefix': [], 'single_chat_reply_prefix': '[bot] ', 'group_chat_prefix': ['搜'], 'group_name_white_list': ['A7❤️进群看群公告', '诗词配音素材群', 'A6❤️短剧看群公告'], 'image_create_prefix': ['画'], 'speech_recognition': True, 'group_speech_recognition': False, 'voice_reply_voice': False, 'conversation_max_tokens': 2500, 'expires_in_seconds': 3600, 'character_desc': '你是基于大语言模型的AI智能助手，旨在回答并解决人们的任何问题，并且可以使用多种语言与人交流。', 'temperature': 0.7, 'subscribe_msg': '感谢您的关注！\n这里是AI智能助手，可以自由对话。\n支持语音对话。\n支持图片输入。\n支持图片输出，画字开头的消息将按要求创作图片。\n支持tool、角色扮演和文字冒险等丰富的插件。\n输入{trigger_prefix}#help 查看详细指令。', 'use_linkai': False, 'linkai_api_key': '*****', 'linkai_app_code': '', 'group_welcome_msg': '欢迎新朋友入群\n免费搜剧格式为：\n\n搜xxx（xxx为剧名）\n剧名前面加个搜字'}
[INFO][2024-10-27 19:13:16][config.py:226] - [Config] User datas loaded.
[INFO][2024-10-27 19:13:16][plugin_manager.py:50] - Loading plugins config...
[INFO][2024-10-27 19:13:16][plugin_manager.py:88] - Scaning plugins ...
[INFO][2024-10-27 19:13:16][plugin_manager.py:41] - Plugin Banwords_v1.0 registered, path=./plugins\banwords
[INFO][2024-10-27 19:13:16][plugin_manager.py:41] - Plugin BDunit_v0.1 registered, path=./plugins\bdunit
[INFO][2024-10-27 19:13:16][plugin_manager.py:41] - Plugin Dungeon_v1.0 registered, path=./plugins\dungeon
[INFO][2024-10-27 19:13:16][plugin_manager.py:41] - Plugin Finish_v1.0 registered, path=./plugins\finish
[INFO][2024-10-27 19:13:16][plugin_manager.py:41] - Plugin Godcmd_v1.0 registered, path=./plugins\godcmd
[INFO][2024-10-27 19:13:16][plugin_manager.py:41] - Plugin Hello_v0.1 registered, path=./plugins\hello
[INFO][2024-10-27 19:13:16][plugin_manager.py:41] - Plugin Keyword_v0.1 registered, path=./plugins\keyword
[INFO][2024-10-27 19:13:16][plugin_manager.py:41] - Plugin linkai_v0.1.0 registered, path=./plugins\linkai
[INFO][2024-10-27 19:13:16][plugin_manager.py:41] - Plugin Role_v1.0 registered, path=./plugins\role
[WARNING][2024-10-27 19:13:16][plugin_manager.py:113] - Failed to import plugin tool: No module named 'chatgpt_tool_hub'
[INFO][2024-10-27 19:13:16][godcmd.py:194] - [Godcmd] 因未设置口令，本次的临时口令为8167。
[INFO][2024-10-27 19:13:16][godcmd.py:210] - [Godcmd] inited
[INFO][2024-10-27 19:13:16][keyword.py:40] - [keyword] {}
[INFO][2024-10-27 19:13:16][keyword.py:42] - [keyword] inited.
[INFO][2024-10-27 19:13:16][linkai.py:35] - [LinkAI] inited, config={'group_app_map': {'测试群名1': 'default', '测试群名2': 'Kv2fXJcH'}, 'midjourney': {'enabled': False, 'auto_translate': True, 'img_proxy': True, 'max_tasks': 3, 'max_tasks_per_user': 1, 'use_image_create_prefix': True}, 'summary': {'enabled': False, 'group_enabled': True, 'max_file_size': 5000, 'type': ['FILE', 'SHARING']}}
[INFO][2024-10-27 19:13:16][role.py:69] - [Role] inited
[INFO][2024-10-27 19:13:16][dungeon.py:56] - [Dungeon] inited
[INFO][2024-10-27 19:13:16][hello.py:40] - [Hello] inited
[INFO][2024-10-27 19:13:16][finish.py:23] - [Finish] inited
[INFO][2024-10-27 19:16:04][wechat_channel.py:131] - Wechat login success, user_id: @4b9d263ad237ab5bfa0aff46b925d94e2c30aa89ff71a26477810e874785403a, nickname: bot
[WARNING][2024-10-27 19:16:11][role.py:103] - 不支持的bot: coze
[INFO][2024-10-27 19:16:11][bridge.py:70] - create bot coze for chat
[INFO][2024-10-27 19:16:11][bytedance_coze_bot.py:26] - [COZE] query=13111
[WARNING][2024-10-27 19:16:11][chat_gpt_session.py:86] - num_tokens_from_messages() is not implemented for model coze. Returning num tokens assuming gpt-3.5-turbo.
[ERROR][2024-10-27 19:16:26][chat_channel.py:291] - [chat_channel] sendMsg error: HTTPSConnectionPool(host='wx2.qq.com', port=443): Max retries exceeded with url: /cgi-bin/mmwebwx-bin/webwxsendmsg (Caused by ProxyError('Unable to connect to proxy', RemoteDisconnected('Remote end closed connection without response')))
[ERROR][2024-10-27 19:16:26][chat_channel.py:294] - HTTPSConnectionPool(host='wx2.qq.com', port=443): Max retries exceeded with url: /cgi-bin/mmwebwx-bin/webwxsendmsg (Caused by ProxyError('Unable to connect to proxy', RemoteDisconnected('Remote end closed connection without response')))
Traceback (most recent call last):
  File "C:\Users\Administrator\AppData\Local\Programs\Python\Python311\Lib\site-packages\urllib3\connectionpool.py", line 793, in urlopen
    response = self._make_request(
               ^^^^^^^^^^^^^^^^^^^
  File "C:\Users\Administrator\AppData\Local\Programs\Python\Python311\Lib\site-packages\urllib3\connectionpool.py", line 537, in _make_request
    response = conn.getresponse()
               ^^^^^^^^^^^^^^^^^^
  File "C:\Users\Administrator\AppData\Local\Programs\Python\Python311\Lib\site-packages\urllib3\connection.py", line 466, in getresponse
    httplib_response = super().getresponse()
                       ^^^^^^^^^^^^^^^^^^^^^
  File "C:\Users\Administrator\AppData\Local\Programs\Python\Python311\Lib\http\client.py", line 1395, in getresponse
    response.begin()
  File "C:\Users\Administrator\AppData\Local\Programs\Python\Python311\Lib\http\client.py", line 325, in begin
    version, status, reason = self._read_status()
                              ^^^^^^^^^^^^^^^^^^^
  File "C:\Users\Administrator\AppData\Local\Programs\Python\Python311\Lib\http\client.py", line 294, in _read_status
    raise RemoteDisconnected("Remote end closed connection without"
http.client.RemoteDisconnected: Remote end closed connection without response

The above exception was the direct cause of the following exception:

urllib3.exceptions.ProxyError: ('Unable to connect to proxy', RemoteDisconnected('Remote end closed connection without response'))

The above exception was the direct cause of the following exception:

Traceback (most recent call last):
  File "C:\Users\Administrator\AppData\Local\Programs\Python\Python311\Lib\site-packages\requests\adapters.py", line 486, in send
    resp = conn.urlopen(
           ^^^^^^^^^^^^^
  File "C:\Users\Administrator\AppData\Local\Programs\Python\Python311\Lib\site-packages\urllib3\connectionpool.py", line 847, in urlopen
    retries = retries.increment(
              ^^^^^^^^^^^^^^^^^^
  File "C:\Users\Administrator\AppData\Local\Programs\Python\Python311\Lib\site-packages\urllib3\util\retry.py", line 515, in increment
    raise MaxRetryError(_pool, url, reason) from reason  # type: ignore[arg-type]
    ^^^^^^^^^^^^^^^^^^^^^^^^^^^^^^^^^^^^^^^^^^^^^^^^^^^
urllib3.exceptions.MaxRetryError: HTTPSConnectionPool(host='wx2.qq.com', port=443): Max retries exceeded with url: /cgi-bin/mmwebwx-bin/webwxsendmsg (Caused by ProxyError('Unable to connect to proxy', RemoteDisconnected('Remote end closed connection without response')))

During handling of the above exception, another exception occurred:

Traceback (most recent call last):
  File "E:\code\cozewechat\chatgpt-on-wechat\channel\chat_channel.py", line 289, in _send
    self.send(reply, context)
  File "E:\code\cozewechat\chatgpt-on-wechat\channel\wechat\wechat_channel.py", line 213, in send
    itchat.send(reply.content, toUserName=receiver)
  File "E:\code\cozewechat\chatgpt-on-wechat\lib\itchat\components\messages.py", line 513, in send
    r = self.send_msg(msg, toUserName)
        ^^^^^^^^^^^^^^^^^^^^^^^^^^^^^^
  File "E:\code\cozewechat\chatgpt-on-wechat\lib\itchat\components\messages.py", line 283, in send_msg
    r = self.send_raw_msg(1, msg, toUserName)
        ^^^^^^^^^^^^^^^^^^^^^^^^^^^^^^^^^^^^^
  File "E:\code\cozewechat\chatgpt-on-wechat\lib\itchat\components\messages.py", line 277, in send_raw_msg
    r = self.s.post(url, headers=headers,
        ^^^^^^^^^^^^^^^^^^^^^^^^^^^^^^^^^
  File "C:\Users\Administrator\AppData\Local\Programs\Python\Python311\Lib\site-packages\requests\sessions.py", line 637, in post
    return self.request("POST", url, data=data, json=json, **kwargs)
           ^^^^^^^^^^^^^^^^^^^^^^^^^^^^^^^^^^^^^^^^^^^^^^^^^^^^^^^^^
  File "C:\Users\Administrator\AppData\Local\Programs\Python\Python311\Lib\site-packages\requests\sessions.py", line 589, in request
    resp = self.send(prep, **send_kwargs)
           ^^^^^^^^^^^^^^^^^^^^^^^^^^^^^^
  File "C:\Users\Administrator\AppData\Local\Programs\Python\Python311\Lib\site-packages\requests\sessions.py", line 703, in send
    r = adapter.send(request, **kwargs)
        ^^^^^^^^^^^^^^^^^^^^^^^^^^^^^^^
  File "C:\Users\Administrator\AppData\Local\Programs\Python\Python311\Lib\site-packages\requests\adapters.py", line 513, in send
    raise ProxyError(e, request=request)
requests.exceptions.ProxyError: HTTPSConnectionPool(host='wx2.qq.com', port=443): Max retries exceeded with url: /cgi-bin/mmwebwx-bin/webwxsendmsg (Caused by ProxyError('Unable to connect to proxy', RemoteDisconnected('Remote end closed connection without response')))
[INFO][2024-10-27 19:16:30][wechat_channel.py:214] - [WX] sendMsg=Reply(type=TEXT, content=@璐璐不吃糖
为你搜索到短剧信息如下：
🎬 短剧名称：13111-玄学大佬她直播惊艳全球（47集）马铭婕
📁 短剧链接：https://pan.quark.cn/s/8313e05fc3a8), receiver=@@0965ee617dd801756f3921d7adc0aa13d6afcbae6b5a06340d84e383acb34588
[INFO][2024-10-27 19:17:53][wechat_channel.py:214] - [WX] sendMsg=Reply(type=TEXT, content=@A妞妞
欢迎新朋友入群
免费搜剧格式为：

搜xxx（xxx为剧名）
剧名前面加个搜字), receiver=@@e9e56cc2d07ec38df932714dafde1de2fcc89d55cd8dcd98c41442f8229aa85b
[WARNING][2024-10-27 19:18:18][role.py:103] - 不支持的bot: coze
[INFO][2024-10-27 19:18:18][bytedance_coze_bot.py:26] - [COZE] query=玄学大佬
[WARNING][2024-10-27 19:18:18][chat_gpt_session.py:86] - num_tokens_from_messages() is not implemented for model coze. Returning num tokens assuming gpt-3.5-turbo.
[ERROR][2024-10-27 19:18:33][chat_channel.py:291] - [chat_channel] sendMsg error: HTTPSConnectionPool(host='wx2.qq.com', port=443): Max retries exceeded with url: /cgi-bin/mmwebwx-bin/webwxsendmsg (Caused by ProxyError('Unable to connect to proxy', RemoteDisconnected('Remote end closed connection without response')))
[ERROR][2024-10-27 19:18:33][chat_channel.py:294] - HTTPSConnectionPool(host='wx2.qq.com', port=443): Max retries exceeded with url: /cgi-bin/mmwebwx-bin/webwxsendmsg (Caused by ProxyError('Unable to connect to proxy', RemoteDisconnected('Remote end closed connection without response')))
Traceback (most recent call last):
  File "C:\Users\Administrator\AppData\Local\Programs\Python\Python311\Lib\site-packages\urllib3\connectionpool.py", line 793, in urlopen
    response = self._make_request(
               ^^^^^^^^^^^^^^^^^^^
  File "C:\Users\Administrator\AppData\Local\Programs\Python\Python311\Lib\site-packages\urllib3\connectionpool.py", line 537, in _make_request
    response = conn.getresponse()
               ^^^^^^^^^^^^^^^^^^
  File "C:\Users\Administrator\AppData\Local\Programs\Python\Python311\Lib\site-packages\urllib3\connection.py", line 466, in getresponse
    httplib_response = super().getresponse()
                       ^^^^^^^^^^^^^^^^^^^^^
  File "C:\Users\Administrator\AppData\Local\Programs\Python\Python311\Lib\http\client.py", line 1395, in getresponse
    response.begin()
  File "C:\Users\Administrator\AppData\Local\Programs\Python\Python311\Lib\http\client.py", line 325, in begin
    version, status, reason = self._read_status()
                              ^^^^^^^^^^^^^^^^^^^
  File "C:\Users\Administrator\AppData\Local\Programs\Python\Python311\Lib\http\client.py", line 294, in _read_status
    raise RemoteDisconnected("Remote end closed connection without"
http.client.RemoteDisconnected: Remote end closed connection without response

The above exception was the direct cause of the following exception:

urllib3.exceptions.ProxyError: ('Unable to connect to proxy', RemoteDisconnected('Remote end closed connection without response'))

The above exception was the direct cause of the following exception:

Traceback (most recent call last):
  File "C:\Users\Administrator\AppData\Local\Programs\Python\Python311\Lib\site-packages\requests\adapters.py", line 486, in send
    resp = conn.urlopen(
           ^^^^^^^^^^^^^
  File "C:\Users\Administrator\AppData\Local\Programs\Python\Python311\Lib\site-packages\urllib3\connectionpool.py", line 847, in urlopen
    retries = retries.increment(
              ^^^^^^^^^^^^^^^^^^
  File "C:\Users\Administrator\AppData\Local\Programs\Python\Python311\Lib\site-packages\urllib3\util\retry.py", line 515, in increment
    raise MaxRetryError(_pool, url, reason) from reason  # type: ignore[arg-type]
    ^^^^^^^^^^^^^^^^^^^^^^^^^^^^^^^^^^^^^^^^^^^^^^^^^^^
urllib3.exceptions.MaxRetryError: HTTPSConnectionPool(host='wx2.qq.com', port=443): Max retries exceeded with url: /cgi-bin/mmwebwx-bin/webwxsendmsg (Caused by ProxyError('Unable to connect to proxy', RemoteDisconnected('Remote end closed connection without response')))

During handling of the above exception, another exception occurred:

Traceback (most recent call last):
  File "E:\code\cozewechat\chatgpt-on-wechat\channel\chat_channel.py", line 289, in _send
    self.send(reply, context)
  File "E:\code\cozewechat\chatgpt-on-wechat\channel\wechat\wechat_channel.py", line 213, in send
    itchat.send(reply.content, toUserName=receiver)
  File "E:\code\cozewechat\chatgpt-on-wechat\lib\itchat\components\messages.py", line 513, in send
    r = self.send_msg(msg, toUserName)
        ^^^^^^^^^^^^^^^^^^^^^^^^^^^^^^
  File "E:\code\cozewechat\chatgpt-on-wechat\lib\itchat\components\messages.py", line 283, in send_msg
    r = self.send_raw_msg(1, msg, toUserName)
        ^^^^^^^^^^^^^^^^^^^^^^^^^^^^^^^^^^^^^
  File "E:\code\cozewechat\chatgpt-on-wechat\lib\itchat\components\messages.py", line 277, in send_raw_msg
    r = self.s.post(url, headers=headers,
        ^^^^^^^^^^^^^^^^^^^^^^^^^^^^^^^^^
  File "C:\Users\Administrator\AppData\Local\Programs\Python\Python311\Lib\site-packages\requests\sessions.py", line 637, in post
    return self.request("POST", url, data=data, json=json, **kwargs)
           ^^^^^^^^^^^^^^^^^^^^^^^^^^^^^^^^^^^^^^^^^^^^^^^^^^^^^^^^^
  File "C:\Users\Administrator\AppData\Local\Programs\Python\Python311\Lib\site-packages\requests\sessions.py", line 589, in request
    resp = self.send(prep, **send_kwargs)
           ^^^^^^^^^^^^^^^^^^^^^^^^^^^^^^
  File "C:\Users\Administrator\AppData\Local\Programs\Python\Python311\Lib\site-packages\requests\sessions.py", line 703, in send
    r = adapter.send(request, **kwargs)
        ^^^^^^^^^^^^^^^^^^^^^^^^^^^^^^^
  File "C:\Users\Administrator\AppData\Local\Programs\Python\Python311\Lib\site-packages\requests\adapters.py", line 513, in send
    raise ProxyError(e, request=request)
requests.exceptions.ProxyError: HTTPSConnectionPool(host='wx2.qq.com', port=443): Max retries exceeded with url: /cgi-bin/mmwebwx-bin/webwxsendmsg (Caused by ProxyError('Unable to connect to proxy', RemoteDisconnected('Remote end closed connection without response')))
[INFO][2024-10-27 19:18:37][wechat_channel.py:214] - [WX] sendMsg=Reply(type=TEXT, content=@一壶一茶🍵
为你搜索到短剧信息如下：
🎬 短剧名称：12800-军训求雨我玄学大佬的身份瞒不住了（51集）
📁 短剧链接：https://pan.quark.cn/s/0c2699f2b137
🎬 短剧名称：13111-玄学大佬她直播惊艳全球（47集）马铭婕
📁 短剧链接：https://pan.quark.cn/s/8313e05fc3a8
🎬 短剧名称：12497-玄学大佬惊艳全球（59集）左一
📁 短剧链接：https://pan.quark.cn/s/da74a2db074f), receiver=@@e9e56cc2d07ec38df932714dafde1de2fcc89d55cd8dcd98c41442f8229aa85b
[INFO][2024-10-27 19:51:24][wechat_channel.py:214] - [WX] sendMsg=Reply(type=TEXT, content=@🌻聆听逝去的流年🦋、老郭、郭妞另外一个号
欢迎新朋友入群
免费搜剧格式为：

搜xxx（xxx为剧名）
剧名前面加个搜字), receiver=@@e9e56cc2d07ec38df932714dafde1de2fcc89d55cd8dcd98c41442f8229aa85b
[INFO][2024-10-27 20:01:03][wechat_channel.py:214] - [WX] sendMsg=Reply(type=TEXT, content=@冬雾寒凉、、珂珂子、触不可及.
欢迎新朋友入群
免费搜剧格式为：

搜xxx（xxx为剧名）
剧名前面加个搜字), receiver=@@e9e56cc2d07ec38df932714dafde1de2fcc89d55cd8dcd98c41442f8229aa85b
[WARNING][2024-10-27 20:05:00][role.py:103] - 不支持的bot: coze
[INFO][2024-10-27 20:05:00][bytedance_coze_bot.py:26] - [COZE] query=13156
[WARNING][2024-10-27 20:05:00][chat_gpt_session.py:86] - num_tokens_from_messages() is not implemented for model coze. Returning num tokens assuming gpt-3.5-turbo.
[INFO][2024-10-27 20:05:09][wechat_channel.py:214] - [WX] sendMsg=Reply(type=TEXT, content=@璐璐不吃糖
为你搜索到短剧信息如下：
🎬 短剧名称：13156-消失的厨神（65集）
📁 短剧链接：https://pan.quark.cn/s/83e964e52327), receiver=@@0965ee617dd801756f3921d7adc0aa13d6afcbae6b5a06340d84e383acb34588
[WARNING][2024-10-27 20:11:42][role.py:103] - 不支持的bot: coze
[INFO][2024-10-27 20:11:42][bytedance_coze_bot.py:26] - [COZE] query=弄春风
[WARNING][2024-10-27 20:11:42][chat_gpt_session.py:86] - num_tokens_from_messages() is not implemented for model coze. Returning num tokens assuming gpt-3.5-turbo.
[INFO][2024-10-27 20:11:51][wechat_channel.py:214] - [WX] sendMsg=Reply(type=TEXT, content=@一壶一茶🍵
为你搜索到短剧信息如下：
🎬 短剧名称：13405-弄春风（99集）张楚萱
📁 短剧链接：https://pan.quark.cn/s/0c6aabbffce0), receiver=@@e9e56cc2d07ec38df932714dafde1de2fcc89d55cd8dcd98c41442f8229aa85b
[INFO][2024-10-27 20:33:16][wechat_channel.py:214] - [WX] sendMsg=Reply(type=TEXT, content=@✨魚尾
欢迎新朋友入群
免费搜剧格式为：

搜xxx（xxx为剧名）
剧名前面加个搜字), receiver=@@e9e56cc2d07ec38df932714dafde1de2fcc89d55cd8dcd98c41442f8229aa85b
[WARNING][2024-10-27 20:33:44][role.py:103] - 不支持的bot: coze
[INFO][2024-10-27 20:33:44][bytedance_coze_bot.py:26] - [COZE] query=昭昭殊荣
[WARNING][2024-10-27 20:33:44][chat_gpt_session.py:86] - num_tokens_from_messages() is not implemented for model coze. Returning num tokens assuming gpt-3.5-turbo.
[INFO][2024-10-27 20:33:52][wechat_channel.py:214] - [WX] sendMsg=Reply(type=TEXT, content=@✨魚尾
为你搜索到短剧信息如下：
🎬 短剧名称：13243-昭昭殊荣（65集）
📁 短剧链接：https://pan.quark.cn/s/b319becef34b), receiver=@@e9e56cc2d07ec38df932714dafde1de2fcc89d55cd8dcd98c41442f8229aa85b
[INFO][2024-10-27 20:38:47][wechat_channel.py:214] - [WX] sendMsg=Reply(type=TEXT, content=@z^jiy🧀
欢迎新朋友入群
免费搜剧格式为：

搜xxx（xxx为剧名）
剧名前面加个搜字), receiver=@@e9e56cc2d07ec38df932714dafde1de2fcc89d55cd8dcd98c41442f8229aa85b
[INFO][2024-10-27 20:38:56][wechat_channel.py:214] - [WX] sendMsg=Reply(type=TEXT, content=@能将四水化为波
欢迎新朋友入群
免费搜剧格式为：

搜xxx（xxx为剧名）
剧名前面加个搜字), receiver=@@e9e56cc2d07ec38df932714dafde1de2fcc89d55cd8dcd98c41442f8229aa85b
[WARNING][2024-10-27 20:39:23][role.py:103] - 不支持的bot: coze
[INFO][2024-10-27 20:39:23][bytedance_coze_bot.py:26] - [COZE] query=昭昭殊荣
[WARNING][2024-10-27 20:39:23][chat_gpt_session.py:86] - num_tokens_from_messages() is not implemented for model coze. Returning num tokens assuming gpt-3.5-turbo.
[INFO][2024-10-27 20:39:31][wechat_channel.py:214] - [WX] sendMsg=Reply(type=TEXT, content=@能将四水化为波
为你搜索到短剧信息如下：
🎬 短剧名称：13243-昭昭殊荣（65集）
📁 短剧链接：https://pan.quark.cn/s/b319becef34b), receiver=@@e9e56cc2d07ec38df932714dafde1de2fcc89d55cd8dcd98c41442f8229aa85b
[WARNING][2024-10-27 20:39:33][role.py:103] - 不支持的bot: coze
[INFO][2024-10-27 20:39:33][bytedance_coze_bot.py:26] - [COZE] query=我叫苏妲己
[WARNING][2024-10-27 20:39:33][chat_gpt_session.py:86] - num_tokens_from_messages() is not implemented for model coze. Returning num tokens assuming gpt-3.5-turbo.
[INFO][2024-10-27 20:39:40][wechat_channel.py:214] - [WX] sendMsg=Reply(type=TEXT, content=@z^jiy🧀
为你搜索到短剧信息如下：
🎬 短剧名称：13305-我叫苏妲己（73集）
📁 短剧链接：https://pan.quark.cn/s/0ccb38527d55), receiver=@@e9e56cc2d07ec38df932714dafde1de2fcc89d55cd8dcd98c41442f8229aa85b
[WARNING][2024-10-27 20:42:20][role.py:103] - 不支持的bot: coze
[INFO][2024-10-27 20:42:20][bytedance_coze_bot.py:26] - [COZE] query=弄春风
[WARNING][2024-10-27 20:42:20][chat_gpt_session.py:86] - num_tokens_from_messages() is not implemented for model coze. Returning num tokens assuming gpt-3.5-turbo.
[INFO][2024-10-27 20:42:27][wechat_channel.py:214] - [WX] sendMsg=Reply(type=TEXT, content=@一壶一茶🍵
为你搜索到短剧信息如下：
🎬 短剧名称：13405-弄春风（99集）张楚萱
📁 短剧链接：https://pan.quark.cn/s/0c6aabbffce0), receiver=@@ead42c52023359561869337d4180d56a6cf9032defbb0f6906c6ad94eaaabc72
[INFO][2024-10-27 20:47:03][wechat_channel.py:214] - [WX] sendMsg=Reply(type=TEXT, content=@💖、冬雾寒凉、、Ella、等风不等雨、触不可及.、章鱼炖菠萝蜜、花魿、吐出来感觉好多了
欢迎新朋友入群
免费搜剧格式为：

搜xxx（xxx为剧名）
剧名前面加个搜字), receiver=@@ead42c52023359561869337d4180d56a6cf9032defbb0f6906c6ad94eaaabc72
[INFO][2024-10-27 20:47:12][wechat_channel.py:214] - [WX] sendMsg=Reply(type=TEXT, content=@珂珂子
欢迎新朋友入群
免费搜剧格式为：

搜xxx（xxx为剧名）
剧名前面加个搜字), receiver=@@ead42c52023359561869337d4180d56a6cf9032defbb0f6906c6ad94eaaabc72
[WARNING][2024-10-27 20:52:41][role.py:103] - 不支持的bot: coze
[INFO][2024-10-27 20:52:41][bytedance_coze_bot.py:26] - [COZE] query=13111
[WARNING][2024-10-27 20:52:41][chat_gpt_session.py:86] - num_tokens_from_messages() is not implemented for model coze. Returning num tokens assuming gpt-3.5-turbo.
[INFO][2024-10-27 20:52:47][wechat_channel.py:214] - [WX] sendMsg=Reply(type=TEXT, content=@璐璐不吃糖
为你搜索到短剧信息如下：), receiver=@@0965ee617dd801756f3921d7adc0aa13d6afcbae6b5a06340d84e383acb34588
[WARNING][2024-10-27 20:53:00][role.py:103] - 不支持的bot: coze
[INFO][2024-10-27 20:53:00][bytedance_coze_bot.py:26] - [COZE] query=13111
[WARNING][2024-10-27 20:53:00][chat_gpt_session.py:86] - num_tokens_from_messages() is not implemented for model coze. Returning num tokens assuming gpt-3.5-turbo.
[INFO][2024-10-27 20:53:10][wechat_channel.py:214] - [WX] sendMsg=Reply(type=TEXT, content=@璐璐不吃糖
为你搜索到短剧信息如下：
🎬 短剧名称：13111-玄学大佬她直播惊艳全球（47集）马铭婕
📁 短剧链接：https://pan.quark.cn/s/8313e05fc3a8), receiver=@@0965ee617dd801756f3921d7adc0aa13d6afcbae6b5a06340d84e383acb34588
[WARNING][2024-10-27 20:53:51][role.py:103] - 不支持的bot: coze
[INFO][2024-10-27 20:53:51][bytedance_coze_bot.py:26] - [COZE] query=13417
[WARNING][2024-10-27 20:53:51][chat_gpt_session.py:86] - num_tokens_from_messages() is not implemented for model coze. Returning num tokens assuming gpt-3.5-turbo.
[INFO][2024-10-27 20:53:58][wechat_channel.py:214] - [WX] sendMsg=Reply(type=TEXT, content=@一壶一茶🍵
为你搜索到短剧信息如下：
🎬 短剧名称：13417-娇蛮千金豪宠总裁上司（69集）张北淅＆王新颖
📁 短剧链接：[点击查看](https://pan.quark.cn/s/b6736c82a3c4)), receiver=@@0965ee617dd801756f3921d7adc0aa13d6afcbae6b5a06340d84e383acb34588
[INFO][2024-10-27 21:06:00][wechat_channel.py:214] - [WX] sendMsg=Reply(type=TEXT, content=@Capybara
欢迎新朋友入群
免费搜剧格式为：

搜xxx（xxx为剧名）
剧名前面加个搜字), receiver=@@ead42c52023359561869337d4180d56a6cf9032defbb0f6906c6ad94eaaabc72
[WARNING][2024-10-27 21:14:28][role.py:103] - 不支持的bot: coze
[INFO][2024-10-27 21:14:28][bytedance_coze_bot.py:26] - [COZE] query=昭昭
[WARNING][2024-10-27 21:14:28][chat_gpt_session.py:86] - num_tokens_from_messages() is not implemented for model coze. Returning num tokens assuming gpt-3.5-turbo.
[INFO][2024-10-27 21:14:36][wechat_channel.py:214] - [WX] sendMsg=Reply(type=TEXT, content=@璐璐不吃糖
请稍等，正在为您搜剧中......), receiver=@@0965ee617dd801756f3921d7adc0aa13d6afcbae6b5a06340d84e383acb34588
[INFO][2024-10-27 21:21:31][app.py:19] - signal 2 received, exiting...
[INFO][2024-10-27 21:21:31][config.py:237] - [Config] User datas saved.
[ERROR][2024-10-27 21:21:57][config.py:264] - Expecting value: line 23 column 3 (char 609)
Traceback (most recent call last):
  File "E:\code\cozewechat\chatgpt-on-wechat\config.py", line 248, in drag_sensitive
    conf_dict: dict = json.loads(config)
                      ^^^^^^^^^^^^^^^^^^
  File "C:\Users\Administrator\AppData\Local\Programs\Python\Python311\Lib\json\__init__.py", line 346, in loads
    return _default_decoder.decode(s)
           ^^^^^^^^^^^^^^^^^^^^^^^^^^
  File "C:\Users\Administrator\AppData\Local\Programs\Python\Python311\Lib\json\decoder.py", line 337, in decode
    obj, end = self.raw_decode(s, idx=_w(s, 0).end())
               ^^^^^^^^^^^^^^^^^^^^^^^^^^^^^^^^^^^^^^
  File "C:\Users\Administrator\AppData\Local\Programs\Python\Python311\Lib\json\decoder.py", line 355, in raw_decode
    raise JSONDecodeError("Expecting value", s, err.value) from None
json.decoder.JSONDecodeError: Expecting value: line 23 column 3 (char 609)
[ERROR][2024-10-27 21:21:57][app.py:66] - App startup failed!
[ERROR][2024-10-27 21:21:57][app.py:67] - Expecting value: line 23 column 3 (char 609)
Traceback (most recent call last):
  File "E:\code\cozewechat\chatgpt-on-wechat\app.py", line 46, in run
    load_config()
  File "E:\code\cozewechat\chatgpt-on-wechat\config.py", line 280, in load_config
    config = Config(json.loads(config_str))
                    ^^^^^^^^^^^^^^^^^^^^^^
  File "C:\Users\Administrator\AppData\Local\Programs\Python\Python311\Lib\json\__init__.py", line 346, in loads
    return _default_decoder.decode(s)
           ^^^^^^^^^^^^^^^^^^^^^^^^^^
  File "C:\Users\Administrator\AppData\Local\Programs\Python\Python311\Lib\json\decoder.py", line 337, in decode
    obj, end = self.raw_decode(s, idx=_w(s, 0).end())
               ^^^^^^^^^^^^^^^^^^^^^^^^^^^^^^^^^^^^^^
  File "C:\Users\Administrator\AppData\Local\Programs\Python\Python311\Lib\json\decoder.py", line 355, in raw_decode
    raise JSONDecodeError("Expecting value", s, err.value) from None
json.decoder.JSONDecodeError: Expecting value: line 23 column 3 (char 609)
[ERROR][2024-10-27 21:22:15][config.py:264] - Expecting value: line 23 column 3 (char 609)
Traceback (most recent call last):
  File "E:\code\cozewechat\chatgpt-on-wechat\config.py", line 248, in drag_sensitive
    conf_dict: dict = json.loads(config)
                      ^^^^^^^^^^^^^^^^^^
  File "C:\Users\Administrator\AppData\Local\Programs\Python\Python311\Lib\json\__init__.py", line 346, in loads
    return _default_decoder.decode(s)
           ^^^^^^^^^^^^^^^^^^^^^^^^^^
  File "C:\Users\Administrator\AppData\Local\Programs\Python\Python311\Lib\json\decoder.py", line 337, in decode
    obj, end = self.raw_decode(s, idx=_w(s, 0).end())
               ^^^^^^^^^^^^^^^^^^^^^^^^^^^^^^^^^^^^^^
  File "C:\Users\Administrator\AppData\Local\Programs\Python\Python311\Lib\json\decoder.py", line 355, in raw_decode
    raise JSONDecodeError("Expecting value", s, err.value) from None
json.decoder.JSONDecodeError: Expecting value: line 23 column 3 (char 609)
[ERROR][2024-10-27 21:22:15][app.py:66] - App startup failed!
[ERROR][2024-10-27 21:22:15][app.py:67] - Expecting value: line 23 column 3 (char 609)
Traceback (most recent call last):
  File "E:\code\cozewechat\chatgpt-on-wechat\app.py", line 46, in run
    load_config()
  File "E:\code\cozewechat\chatgpt-on-wechat\config.py", line 280, in load_config
    config = Config(json.loads(config_str))
                    ^^^^^^^^^^^^^^^^^^^^^^
  File "C:\Users\Administrator\AppData\Local\Programs\Python\Python311\Lib\json\__init__.py", line 346, in loads
    return _default_decoder.decode(s)
           ^^^^^^^^^^^^^^^^^^^^^^^^^^
  File "C:\Users\Administrator\AppData\Local\Programs\Python\Python311\Lib\json\decoder.py", line 337, in decode
    obj, end = self.raw_decode(s, idx=_w(s, 0).end())
               ^^^^^^^^^^^^^^^^^^^^^^^^^^^^^^^^^^^^^^
  File "C:\Users\Administrator\AppData\Local\Programs\Python\Python311\Lib\json\decoder.py", line 355, in raw_decode
    raise JSONDecodeError("Expecting value", s, err.value) from None
json.decoder.JSONDecodeError: Expecting value: line 23 column 3 (char 609)
[ERROR][2024-10-27 21:22:17][config.py:264] - Expecting value: line 23 column 3 (char 609)
Traceback (most recent call last):
  File "E:\code\cozewechat\chatgpt-on-wechat\config.py", line 248, in drag_sensitive
    conf_dict: dict = json.loads(config)
                      ^^^^^^^^^^^^^^^^^^
  File "C:\Users\Administrator\AppData\Local\Programs\Python\Python311\Lib\json\__init__.py", line 346, in loads
    return _default_decoder.decode(s)
           ^^^^^^^^^^^^^^^^^^^^^^^^^^
  File "C:\Users\Administrator\AppData\Local\Programs\Python\Python311\Lib\json\decoder.py", line 337, in decode
    obj, end = self.raw_decode(s, idx=_w(s, 0).end())
               ^^^^^^^^^^^^^^^^^^^^^^^^^^^^^^^^^^^^^^
  File "C:\Users\Administrator\AppData\Local\Programs\Python\Python311\Lib\json\decoder.py", line 355, in raw_decode
    raise JSONDecodeError("Expecting value", s, err.value) from None
json.decoder.JSONDecodeError: Expecting value: line 23 column 3 (char 609)
[ERROR][2024-10-27 21:22:17][app.py:66] - App startup failed!
[ERROR][2024-10-27 21:22:17][app.py:67] - Expecting value: line 23 column 3 (char 609)
Traceback (most recent call last):
  File "E:\code\cozewechat\chatgpt-on-wechat\app.py", line 46, in run
    load_config()
  File "E:\code\cozewechat\chatgpt-on-wechat\config.py", line 280, in load_config
    config = Config(json.loads(config_str))
                    ^^^^^^^^^^^^^^^^^^^^^^
  File "C:\Users\Administrator\AppData\Local\Programs\Python\Python311\Lib\json\__init__.py", line 346, in loads
    return _default_decoder.decode(s)
           ^^^^^^^^^^^^^^^^^^^^^^^^^^
  File "C:\Users\Administrator\AppData\Local\Programs\Python\Python311\Lib\json\decoder.py", line 337, in decode
    obj, end = self.raw_decode(s, idx=_w(s, 0).end())
               ^^^^^^^^^^^^^^^^^^^^^^^^^^^^^^^^^^^^^^
  File "C:\Users\Administrator\AppData\Local\Programs\Python\Python311\Lib\json\decoder.py", line 355, in raw_decode
    raise JSONDecodeError("Expecting value", s, err.value) from None
json.decoder.JSONDecodeError: Expecting value: line 23 column 3 (char 609)
[INFO][2024-10-27 21:22:38][config.py:302] - [INIT] load config: {'channel_type': 'wx', 'model': 'coze', 'coze_api_base': 'https://api.coze.cn/open_api/v2', 'coze_api_key': 'pat*****hv8', 'coze_bot_id': '7429915965967794195', 'text_to_image': 'dall-e-2', 'voice_to_text': 'openai', 'text_to_voice': 'openai', 'proxy': '', 'hot_reload': False, 'single_chat_prefix': [], 'single_chat_reply_prefix': '[bot] ', 'group_chat_prefix': ['搜'], 'group_name_white_list': ['A7❤️进群看群公告', '诗词配音素材群', 'A6❤️短剧看群公告', 'A5❤️短剧看群公告', 'A8❤️短剧看群公告', 'A9❤️短剧看群公告', 'A10❤️短剧看群公告'], 'image_create_prefix': ['画'], 'speech_recognition': True, 'group_speech_recognition': False, 'voice_reply_voice': False, 'conversation_max_tokens': 2500, 'expires_in_seconds': 3600, 'character_desc': '你是基于大语言模型的AI智能助手，旨在回答并解决人们的任何问题，并且可以使用多种语言与人交流。', 'temperature': 0.7, 'subscribe_msg': '感谢您的关注！\n这里是AI智能助手，可以自由对话。\n支持语音对话。\n支持图片输入。\n支持图片输出，画字开头的消息将按要求创作图片。\n支持tool、角色扮演和文字冒险等丰富的插件。\n输入{trigger_prefix}#help 查看详细指令。', 'use_linkai': False, 'linkai_api_key': '*****', 'linkai_app_code': '', 'group_welcome_msg': '欢迎新朋友入群\n\n免费搜剧格式为：\n\n搜xxx（xxx为剧名或序号）\n剧名前面加个搜字'}
[INFO][2024-10-27 21:22:38][config.py:226] - [Config] User datas loaded.
[INFO][2024-10-27 21:22:39][plugin_manager.py:50] - Loading plugins config...
[INFO][2024-10-27 21:22:39][plugin_manager.py:88] - Scaning plugins ...
[INFO][2024-10-27 21:22:39][plugin_manager.py:41] - Plugin Banwords_v1.0 registered, path=./plugins\banwords
[INFO][2024-10-27 21:22:39][plugin_manager.py:41] - Plugin BDunit_v0.1 registered, path=./plugins\bdunit
[INFO][2024-10-27 21:22:39][plugin_manager.py:41] - Plugin Dungeon_v1.0 registered, path=./plugins\dungeon
[INFO][2024-10-27 21:22:39][plugin_manager.py:41] - Plugin Finish_v1.0 registered, path=./plugins\finish
[INFO][2024-10-27 21:22:39][plugin_manager.py:41] - Plugin Godcmd_v1.0 registered, path=./plugins\godcmd
[INFO][2024-10-27 21:22:39][plugin_manager.py:41] - Plugin Hello_v0.1 registered, path=./plugins\hello
[INFO][2024-10-27 21:22:39][plugin_manager.py:41] - Plugin Keyword_v0.1 registered, path=./plugins\keyword
[INFO][2024-10-27 21:22:39][plugin_manager.py:41] - Plugin linkai_v0.1.0 registered, path=./plugins\linkai
[INFO][2024-10-27 21:22:39][plugin_manager.py:41] - Plugin Role_v1.0 registered, path=./plugins\role
[WARNING][2024-10-27 21:22:39][plugin_manager.py:113] - Failed to import plugin tool: No module named 'chatgpt_tool_hub'
[INFO][2024-10-27 21:22:39][godcmd.py:194] - [Godcmd] 因未设置口令，本次的临时口令为6041。
[INFO][2024-10-27 21:22:39][godcmd.py:210] - [Godcmd] inited
[INFO][2024-10-27 21:22:39][keyword.py:40] - [keyword] {}
[INFO][2024-10-27 21:22:39][keyword.py:42] - [keyword] inited.
[INFO][2024-10-27 21:22:39][linkai.py:35] - [LinkAI] inited, config={'group_app_map': {'测试群名1': 'default', '测试群名2': 'Kv2fXJcH'}, 'midjourney': {'enabled': False, 'auto_translate': True, 'img_proxy': True, 'max_tasks': 3, 'max_tasks_per_user': 1, 'use_image_create_prefix': True}, 'summary': {'enabled': False, 'group_enabled': True, 'max_file_size': 5000, 'type': ['FILE', 'SHARING']}}
[INFO][2024-10-27 21:22:39][role.py:69] - [Role] inited
[INFO][2024-10-27 21:22:39][dungeon.py:56] - [Dungeon] inited
[INFO][2024-10-27 21:22:39][hello.py:40] - [Hello] inited
[INFO][2024-10-27 21:22:39][finish.py:23] - [Finish] inited
[INFO][2024-10-27 21:23:16][wechat_channel.py:131] - Wechat login success, user_id: @7f2f356cc728699b6a0b294e5573f321b7eea051e670346583486ebeb231fce6, nickname: bot
[WARNING][2024-10-27 21:23:24][role.py:103] - 不支持的bot: coze
[INFO][2024-10-27 21:23:24][bridge.py:70] - create bot coze for chat
[INFO][2024-10-27 21:23:24][bytedance_coze_bot.py:26] - [COZE] query=昭昭
[WARNING][2024-10-27 21:23:24][chat_gpt_session.py:86] - num_tokens_from_messages() is not implemented for model coze. Returning num tokens assuming gpt-3.5-turbo.
[ERROR][2024-10-27 21:23:24][bytedance_coze_bot.py:33] - [COZE] reply error=[COZE] Error: 未具备相应权限，请查阅对应 API Token文档 如有问题请提交反馈
[INFO][2024-10-27 21:23:24][wechat_channel.py:217] - [WX] sendMsg=Reply(type=ERROR, content=[ERROR]
我暂时遇到了一些问题，请您稍后重试~), receiver=@@373945f0985db8db47acb53148b4bc4e39cf52e339a2620cd45d6818196b65ea
[WARNING][2024-10-27 21:25:23][role.py:103] - 不支持的bot: coze
[INFO][2024-10-27 21:25:23][bytedance_coze_bot.py:26] - [COZE] query=13156
[WARNING][2024-10-27 21:25:23][chat_gpt_session.py:86] - num_tokens_from_messages() is not implemented for model coze. Returning num tokens assuming gpt-3.5-turbo.
[ERROR][2024-10-27 21:25:23][bytedance_coze_bot.py:33] - [COZE] reply error=[COZE] Error: 未具备相应权限，请查阅对应 API Token文档 如有问题请提交反馈
[INFO][2024-10-27 21:25:23][wechat_channel.py:217] - [WX] sendMsg=Reply(type=ERROR, content=[ERROR]
我暂时遇到了一些问题，请您稍后重试~), receiver=@@373945f0985db8db47acb53148b4bc4e39cf52e339a2620cd45d6818196b65ea
[INFO][2024-10-27 21:26:27][app.py:19] - signal 2 received, exiting...
[INFO][2024-10-27 21:26:27][config.py:237] - [Config] User datas saved.
[INFO][2024-10-27 21:26:55][config.py:302] - [INIT] load config: {'channel_type': 'wx', 'model': 'coze', 'coze_api_base': 'https://api.coze.cn/open_api/v2', 'coze_api_key': 'pat*****hv8', 'coze_bot_id': '7430312631141318675', 'text_to_image': 'dall-e-2', 'voice_to_text': 'openai', 'text_to_voice': 'openai', 'proxy': '', 'hot_reload': False, 'single_chat_prefix': [], 'single_chat_reply_prefix': '[bot] ', 'group_chat_prefix': ['搜'], 'group_name_white_list': ['A7❤️进群看群公告', '诗词配音素材群', 'A6❤️短剧看群公告', 'A5❤️短剧看群公告', 'A8❤️短剧看群公告', 'A9❤️短剧看群公告', 'A10❤️短剧看群公告'], 'image_create_prefix': ['画'], 'speech_recognition': True, 'group_speech_recognition': False, 'voice_reply_voice': False, 'conversation_max_tokens': 2500, 'expires_in_seconds': 3600, 'character_desc': '你是基于大语言模型的AI智能助手，旨在回答并解决人们的任何问题，并且可以使用多种语言与人交流。', 'temperature': 0.7, 'subscribe_msg': '感谢您的关注！\n这里是AI智能助手，可以自由对话。\n支持语音对话。\n支持图片输入。\n支持图片输出，画字开头的消息将按要求创作图片。\n支持tool、角色扮演和文字冒险等丰富的插件。\n输入{trigger_prefix}#help 查看详细指令。', 'use_linkai': False, 'linkai_api_key': '*****', 'linkai_app_code': '', 'group_welcome_msg': '欢迎新朋友入群\n\n免费搜剧格式为：\n\n搜xxx（xxx为剧名或序号）\n剧名前面加个搜字'}
[INFO][2024-10-27 21:26:55][config.py:226] - [Config] User datas loaded.
[INFO][2024-10-27 21:26:55][plugin_manager.py:50] - Loading plugins config...
[INFO][2024-10-27 21:26:55][plugin_manager.py:88] - Scaning plugins ...
[INFO][2024-10-27 21:26:55][plugin_manager.py:41] - Plugin Banwords_v1.0 registered, path=./plugins\banwords
[INFO][2024-10-27 21:26:55][plugin_manager.py:41] - Plugin BDunit_v0.1 registered, path=./plugins\bdunit
[INFO][2024-10-27 21:26:55][plugin_manager.py:41] - Plugin Dungeon_v1.0 registered, path=./plugins\dungeon
[INFO][2024-10-27 21:26:55][plugin_manager.py:41] - Plugin Finish_v1.0 registered, path=./plugins\finish
[INFO][2024-10-27 21:26:55][plugin_manager.py:41] - Plugin Godcmd_v1.0 registered, path=./plugins\godcmd
[INFO][2024-10-27 21:26:55][plugin_manager.py:41] - Plugin Hello_v0.1 registered, path=./plugins\hello
[INFO][2024-10-27 21:26:55][plugin_manager.py:41] - Plugin Keyword_v0.1 registered, path=./plugins\keyword
[INFO][2024-10-27 21:26:55][plugin_manager.py:41] - Plugin linkai_v0.1.0 registered, path=./plugins\linkai
[INFO][2024-10-27 21:26:55][plugin_manager.py:41] - Plugin Role_v1.0 registered, path=./plugins\role
[WARNING][2024-10-27 21:26:55][plugin_manager.py:113] - Failed to import plugin tool: No module named 'chatgpt_tool_hub'
[INFO][2024-10-27 21:26:55][godcmd.py:194] - [Godcmd] 因未设置口令，本次的临时口令为9024。
[INFO][2024-10-27 21:26:55][godcmd.py:210] - [Godcmd] inited
[INFO][2024-10-27 21:26:55][keyword.py:40] - [keyword] {}
[INFO][2024-10-27 21:26:55][keyword.py:42] - [keyword] inited.
[INFO][2024-10-27 21:26:55][linkai.py:35] - [LinkAI] inited, config={'group_app_map': {'测试群名1': 'default', '测试群名2': 'Kv2fXJcH'}, 'midjourney': {'enabled': False, 'auto_translate': True, 'img_proxy': True, 'max_tasks': 3, 'max_tasks_per_user': 1, 'use_image_create_prefix': True}, 'summary': {'enabled': False, 'group_enabled': True, 'max_file_size': 5000, 'type': ['FILE', 'SHARING']}}
[INFO][2024-10-27 21:26:55][role.py:69] - [Role] inited
[INFO][2024-10-27 21:26:55][dungeon.py:56] - [Dungeon] inited
[INFO][2024-10-27 21:26:55][hello.py:40] - [Hello] inited
[INFO][2024-10-27 21:26:55][finish.py:23] - [Finish] inited
[INFO][2024-10-27 21:27:20][wechat_channel.py:131] - Wechat login success, user_id: @c6d103dd878578f278b394569f15cb6d85a9762e2301568e3410c0e90818d20a, nickname: bot
[WARNING][2024-10-27 21:27:33][role.py:103] - 不支持的bot: coze
[INFO][2024-10-27 21:27:33][bridge.py:70] - create bot coze for chat
[INFO][2024-10-27 21:27:33][bytedance_coze_bot.py:26] - [COZE] query=13156
[WARNING][2024-10-27 21:27:33][chat_gpt_session.py:86] - num_tokens_from_messages() is not implemented for model coze. Returning num tokens assuming gpt-3.5-turbo.
[INFO][2024-10-27 21:27:42][wechat_channel.py:214] - [WX] sendMsg=Reply(type=TEXT, content=@璐璐不吃糖
请稍等，正在为您搜剧中......), receiver=@@940085365da2ca3fc10bdcecbafc56490229082addf967c1821c6a9725540052
[WARNING][2024-10-27 21:28:07][role.py:103] - 不支持的bot: coze
[INFO][2024-10-27 21:28:07][bytedance_coze_bot.py:26] - [COZE] query=昭昭
[WARNING][2024-10-27 21:28:07][chat_gpt_session.py:86] - num_tokens_from_messages() is not implemented for model coze. Returning num tokens assuming gpt-3.5-turbo.
[INFO][2024-10-27 21:28:14][wechat_channel.py:214] - [WX] sendMsg=Reply(type=TEXT, content=@璐璐不吃糖
请稍等，正在为您搜剧中......), receiver=@@940085365da2ca3fc10bdcecbafc56490229082addf967c1821c6a9725540052
[WARNING][2024-10-27 21:29:03][role.py:103] - 不支持的bot: coze
[INFO][2024-10-27 21:29:03][bytedance_coze_bot.py:26] - [COZE] query=昭昭
[WARNING][2024-10-27 21:29:03][chat_gpt_session.py:86] - num_tokens_from_messages() is not implemented for model coze. Returning num tokens assuming gpt-3.5-turbo.
[INFO][2024-10-27 21:29:12][wechat_channel.py:214] - [WX] sendMsg=Reply(type=TEXT, content=@璐璐不吃糖
为你搜索到短剧信息如下：
🎬 短剧名称：13243-昭昭殊荣（65集）
📁 短剧链接：https://pan.quark.cn/s/b319becef34b

下载夸克APP转存至网盘观看，未保存到网盘只能试看两分钟
按文件名排序可以从第一集开始自动播), receiver=@@940085365da2ca3fc10bdcecbafc56490229082addf967c1821c6a9725540052
[WARNING][2024-10-27 21:30:10][role.py:103] - 不支持的bot: coze
[INFO][2024-10-27 21:30:10][bytedance_coze_bot.py:26] - [COZE] query=13417
[WARNING][2024-10-27 21:30:10][chat_gpt_session.py:86] - num_tokens_from_messages() is not implemented for model coze. Returning num tokens assuming gpt-3.5-turbo.
[INFO][2024-10-27 21:30:23][wechat_channel.py:214] - [WX] sendMsg=Reply(type=TEXT, content=@一壶一茶🍵
为你搜索到短剧信息如下：
🎬 短剧名称：13417-娇蛮千金豪宠总裁上司（69集）张北淅＆王新颖
📁 短剧链接：https://pan.quark.cn/s/b6736c82a3c4

下载夸克APP转存至网盘观看，未保存到网盘只能试看两分钟
按文件名排序可以从第一集开始自动播), receiver=@@940085365da2ca3fc10bdcecbafc56490229082addf967c1821c6a9725540052
[INFO][2024-10-27 21:36:32][wechat_channel.py:214] - [WX] sendMsg=Reply(type=TEXT, content=@Zmmin
欢迎新朋友入群

免费搜剧格式为：

搜xxx（xxx为剧名或序号）
剧名前面加个搜字), receiver=@@567153b8a295f931280227a4b3ab812fe2e321603fe24981ebd564c28663e097
[INFO][2024-10-27 21:38:33][wechat_channel.py:214] - [WX] sendMsg=Reply(type=TEXT, content=@一秒十
欢迎新朋友入群

免费搜剧格式为：

搜xxx（xxx为剧名或序号）
剧名前面加个搜字), receiver=@@567153b8a295f931280227a4b3ab812fe2e321603fe24981ebd564c28663e097
[WARNING][2024-10-27 21:39:03][role.py:103] - 不支持的bot: coze
[INFO][2024-10-27 21:39:03][bytedance_coze_bot.py:26] - [COZE] query=偷听心声
[WARNING][2024-10-27 21:39:03][chat_gpt_session.py:86] - num_tokens_from_messages() is not implemented for model coze. Returning num tokens assuming gpt-3.5-turbo.
[INFO][2024-10-27 21:39:12][wechat_channel.py:214] - [WX] sendMsg=Reply(type=TEXT, content=@🌼王者荣耀 🦋
搜剧失败，暂无此资源。

请检查剧名是否正确！), receiver=@@567153b8a295f931280227a4b3ab812fe2e321603fe24981ebd564c28663e097
[WARNING][2024-10-27 21:39:46][role.py:103] - 不支持的bot: coze
[INFO][2024-10-27 21:39:46][bytedance_coze_bot.py:26] - [COZE] query=13417
[WARNING][2024-10-27 21:39:46][chat_gpt_session.py:86] - num_tokens_from_messages() is not implemented for model coze. Returning num tokens assuming gpt-3.5-turbo.
[INFO][2024-10-27 21:39:57][wechat_channel.py:214] - [WX] sendMsg=Reply(type=TEXT, content=@🌼王者荣耀 🦋
为你搜索到短剧信息如下：
🎬 短剧名称：13417-娇蛮千金豪宠总裁上司（69集）张北淅＆王新颖
📁 短剧链接：https://pan.quark.cn/s/b6736c82a3c4

下载夸克APP转存至网盘观看，未保存到网盘只能试看两分钟
按文件名排序可以从第一集开始自动播), receiver=@@567153b8a295f931280227a4b3ab812fe2e321603fe24981ebd564c28663e097
[WARNING][2024-10-27 21:40:17][role.py:103] - 不支持的bot: coze
[INFO][2024-10-27 21:40:17][bytedance_coze_bot.py:26] - [COZE] query=重生后我被京圈太子爷宠上天
[WARNING][2024-10-27 21:40:17][chat_gpt_session.py:86] - num_tokens_from_messages() is not implemented for model coze. Returning num tokens assuming gpt-3.5-turbo.
[INFO][2024-10-27 21:40:28][wechat_channel.py:214] - [WX] sendMsg=Reply(type=TEXT, content=@一秒十
为你搜索到短剧信息如下：
🎬 短剧名称：13372-重生后我被京圈太子爷宠上天（78集）申浩男&钟熙
📁 短剧链接：https://pan.quark.cn/s/32b6a9e78daa

下载夸克APP转存至网盘观看，未保存到网盘只能试看两分钟
按文件名排序可以从第一集开始自动播), receiver=@@567153b8a295f931280227a4b3ab812fe2e321603fe24981ebd564c28663e097
[INFO][2024-10-27 21:40:50][wechat_channel.py:214] - [WX] sendMsg=Reply(type=TEXT, content=@No
欢迎新朋友入群

免费搜剧格式为：

搜xxx（xxx为剧名或序号）
剧名前面加个搜字), receiver=@@567153b8a295f931280227a4b3ab812fe2e321603fe24981ebd564c28663e097
[WARNING][2024-10-27 21:53:36][role.py:103] - 不支持的bot: coze
[INFO][2024-10-27 21:53:36][bytedance_coze_bot.py:26] - [COZE] query=前妻攻略
[WARNING][2024-10-27 21:53:36][chat_gpt_session.py:86] - num_tokens_from_messages() is not implemented for model coze. Returning num tokens assuming gpt-3.5-turbo.
[INFO][2024-10-27 21:53:46][wechat_channel.py:214] - [WX] sendMsg=Reply(type=TEXT, content=@Q.
为你搜索到短剧信息如下：
🎬 短剧名称：6246-前妻攻略：傅先生乖乖宠我（106集）戴不动
📁 短剧链接：https://pan.quark.cn/s/88af31dcb906
🎬 短剧名称：6246-前妻攻略：傅先生乖乖宠我（106集）戴不动
📁 短剧链接：https://pan.quark.cn/s/3a3d627dbcee

下载夸克APP转存至网盘观看，未保存到网盘只能试看两分钟
按文件名排序可以从第一集开始自动播), receiver=@@f7c1a257647300d2821aa505e781d44c0ab4ba33d479220ba2fe391979a1587b
[WARNING][2024-10-27 21:54:37][role.py:103] - 不支持的bot: coze
[INFO][2024-10-27 21:54:37][bytedance_coze_bot.py:26] - [COZE] query=重生后我竟是京圈太子爷的白月光
[WARNING][2024-10-27 21:54:37][chat_gpt_session.py:86] - num_tokens_from_messages() is not implemented for model coze. Returning num tokens assuming gpt-3.5-turbo.
[INFO][2024-10-27 21:54:43][wechat_channel.py:214] - [WX] sendMsg=Reply(type=TEXT, content=@✨魚尾
搜剧失败，暂无此资源。

请检查剧名是否正确！), receiver=@@f7c3704e7b89a67e7250e17330f280c2834611298f7f78201c3f1a218f0e71eb
[WARNING][2024-10-27 21:55:16][role.py:103] - 不支持的bot: coze
[INFO][2024-10-27 21:55:16][bytedance_coze_bot.py:26] - [COZE] query=京圈太子爷的白月光
[WARNING][2024-10-27 21:55:16][chat_gpt_session.py:86] - num_tokens_from_messages() is not implemented for model coze. Returning num tokens assuming gpt-3.5-turbo.
[INFO][2024-10-27 21:55:23][wechat_channel.py:214] - [WX] sendMsg=Reply(type=TEXT, content=@璐璐不吃糖
搜剧失败，暂无此资源。

请检查剧名是否正确！), receiver=@@940085365da2ca3fc10bdcecbafc56490229082addf967c1821c6a9725540052
[INFO][2024-10-27 21:55:59][wechat_channel.py:214] - [WX] sendMsg=Reply(type=TEXT, content=@黑哥💋
欢迎新朋友入群

免费搜剧格式为：

搜xxx（xxx为剧名或序号）
剧名前面加个搜字), receiver=@@567153b8a295f931280227a4b3ab812fe2e321603fe24981ebd564c28663e097
[WARNING][2024-10-27 21:56:51][role.py:103] - 不支持的bot: coze
[INFO][2024-10-27 21:56:51][bytedance_coze_bot.py:26] - [COZE] query=重生后我被京圈太子爷宠上天
[WARNING][2024-10-27 21:56:51][chat_gpt_session.py:86] - num_tokens_from_messages() is not implemented for model coze. Returning num tokens assuming gpt-3.5-turbo.
[INFO][2024-10-27 21:57:02][wechat_channel.py:214] - [WX] sendMsg=Reply(type=TEXT, content=@✨魚尾
为你搜索到短剧信息如下：
🎬 短剧名称：13372-重生后我被京圈太子爷宠上天（78集）申浩男&钟熙
📁 短剧链接：https://pan.quark.cn/s/32b6a9e78daa

下载夸克APP转存至网盘观看，未保存到网盘只能试看两分钟
按文件名排序可以从第一集开始自动播), receiver=@@f7c3704e7b89a67e7250e17330f280c2834611298f7f78201c3f1a218f0e71eb
[WARNING][2024-10-27 21:57:27][role.py:103] - 不支持的bot: coze
[INFO][2024-10-27 21:57:27][bytedance_coze_bot.py:26] - [COZE] query=玄学大佬
[WARNING][2024-10-27 21:57:27][chat_gpt_session.py:86] - num_tokens_from_messages() is not implemented for model coze. Returning num tokens assuming gpt-3.5-turbo.
[INFO][2024-10-27 21:57:38][wechat_channel.py:214] - [WX] sendMsg=Reply(type=TEXT, content=@璐璐不吃糖
为你搜索到短剧信息如下：
🎬 短剧名称：13111-玄学大佬她直播惊艳全球（47集）马铭婕
📁 短剧链接：https://pan.quark.cn/s/8313e05fc3a8
🎬 短剧名称：12497-玄学大佬惊艳全球（59集）左一
📁 短剧链接：https://pan.quark.cn/s/da74a2db074f

下载夸克APP转存至网盘观看，未保存到网盘只能试看两分钟
按文件名排序可以从第一集开始自动播), receiver=@@567153b8a295f931280227a4b3ab812fe2e321603fe24981ebd564c28663e097
